Workbook

Sheet Sumario
E1: Atenção: Não mudar o nome da planilha (Perguntas para o Francisco )
X2: Inicio ano | Y2: 46023
E3: Histórico de geração | X3: data de hoje | Y3: =TODAY() -> 46118 | Z3: =Y3 -> 46118 | AA3: =Y3-Y4+1 -> 46113 | AD3: Máxima - Histórico de geração
E4: Descrição | F4: SPE 1 | G4: SPE 2 | H4: SPE 3 | I4: SPE 5 | J4: SPE 6 | K4: Total | X4: dia atual | Y4: =DAY(Y3) -> 6 | AT4: SPE 1 | AU4: SPE 2 | AV4: SPE 3 | AW4: SPE 5 | AX4: SM
E5: ="Geração de eletricidade acumulada em "&LEFT(PROPER(TEXT(Y3,"mmmm")),3)&"/"&YEAR(Y3)&"" -> Geração de eletricidade acumulada em Abr/2026 | F5: =HLOOKUP($Z$3,'USINA 01 - Barreirinhas'!$CI$4:$CT$8,2) -> 2053.8 | G5: =HLOOKUP($Z$3,'USINA 02 - Barreirinhas'!$CI$4:$CT$8,2) -> 2063.4 | H5: =HLOOKUP($Z$3,'USINA 03 - Barreirinhas'!$CI$4:$CT$8,2) -> 0 | I5: =HLOOKUP($Z$3,'USINA 05 - Barreirinhas'!$CI$4:$CT$8,2) -> 1888.1 | J5: =HLOOKUP($Z$3,'USINA 06 - Barreirinhas'!$CI$4:$CT$8,2) -> 2059.9 | K5: =SUM(F5:J5) -> 8065.2 | X5: mês atual | Y5: =MONTH(Y3) -> 4 | AD5: =MAX(F5:J5) -> 2063.4 | AI5: =AI6-31 -> 45753 | AJ5: =AK5 -> 45717 | AK5: =EOMONTH(AI5,-2)+1 -> 45717 | AL5: SPE 1 | AM5: SPE 2 | AN5: SPE 3 | AO5: SPE 5 | AP5: SM | AS5: 44927 | AT5: {=TRANSPOSE('USINA 01 - Barreirinhas'!I6:T6)} -> 0 | AU5: {=TRANSPOSE('USINA 02 - Barreirinhas'!I6:T6)} -> 0 | AV5: {=TRANSPOSE('USINA 03 - Barreirinhas'!I6:T6)} -> 0 | AW5: {=TRANSPOSE('USINA 05 - Barreirinhas'!J6:U6)} -> 0 | AX5: {=TRANSPOSE('USINA 06 - Barreirinhas'!I6:T6)} -> 0
E6: ="Geração de eletricidade acumulada em "&YEAR(Y3)&"" -> Geração de eletricidade acumulada em 2026 | F6: =HLOOKUP("Total",'USINA 01 - Barreirinhas'!$CI$4:$CU$8,2) -> 37721.4 | G6: =HLOOKUP("Total",'USINA 02 - Barreirinhas'!$CI$4:$CU$8,2) -> 42010.4 | H6: =HLOOKUP("Total",'USINA 03 - Barreirinhas'!$CI$4:$CU$8,2) -> 37705.5 | I6: =HLOOKUP("Total",'USINA 05 - Barreirinhas'!$CI$4:$CU$8,2) -> 39559.6 | J6: =HLOOKUP("Total",'USINA 06 - Barreirinhas'!$CI$4:$CU$8,2) -> 42452.4 | K6: =SUM(F6:J6) -> 199449.3 | X6: ano atual | Y6: =YEAR(Y3) -> 2026 | AA6: =EOMONTH(AA3,-1) -> 46112 | AD6: =MAX(F6:J6) -> 42452.4 | AH6: 1 | AI6: =AI7-31 -> 45784 | AJ6: =AK6 -> 45748 | AK6: =EOMONTH(AI6,-2)+1 -> 45748 | AL6: =VLOOKUP(AJ6,$AS$5:$AX$52,2,FALSE) -> 13720.3 | AM6: =VLOOKUP(AJ6,$AS$5:$AX$52,3,FALSE) -> 13883.2 | AN6: =VLOOKUP(AJ6,$AS$5:$AX$52,4,FALSE) -> 11937.5 | AO6: =VLOOKUP(AJ6,$AS$5:$AX$52,5,FALSE) -> 11535.9 | AP6: =VLOOKUP(AJ6,$AS$5:$AX$52,6,FALSE) -> 13580.7 | AS6: 44958 | AT6: 10149.7 | AU6: 0 | AV6: 0 | AW6: 0 | AX6: 0
E7: ="Média de geração de eletricidade em "&LEFT(PROPER(TEXT(Y3,"mmmm")),3)&"/"&YEAR(Y3)&"" -> Média de geração de eletricidade em Abr/2026 | F7: =IFERROR(HLOOKUP($Z$3,'USINA 01 - Barreirinhas'!$CI$4:$CT$8,5),0) -> 410.76 | G7: =IFERROR(HLOOKUP($Z$3,'USINA 02 - Barreirinhas'!$CI$4:$CT$8,5),0) -> 412.68 | H7: =IFERROR(HLOOKUP($Z$3,'USINA 03 - Barreirinhas'!$CI$4:$CT$8,5),0) -> 0 | I7: =IFERROR(HLOOKUP($Z$3,'USINA 05 - Barreirinhas'!$CI$4:$CT$8,5),0) -> 377.62 | J7: =IFERROR(HLOOKUP($Z$3,'USINA 06 - Barreirinhas'!$CI$4:$CT$8,5),0) -> 411.98 | K7: - | X7: Dias no ano | Y7: =Y3-Y2 -> 95 | AD7: =MAX(F7:J7) -> 412.68 | AH7: =AH6+1 -> 2 | AI7: =AI8-31 -> 45815 | AJ7: =AK7 -> 45778 | AK7: =EOMONTH(AI7,-2)+1 -> 45778 | AL7: =VLOOKUP(AJ7,$AS$5:$AX$52,2,FALSE) -> 14433.7 | AM7: =VLOOKUP(AJ7,$AS$5:$AX$52,3,FALSE) -> 14553.5 | AN7: =VLOOKUP(AJ7,$AS$5:$AX$52,4,FALSE) -> 14278 | AO7: =VLOOKUP(AJ7,$AS$5:$AX$52,5,FALSE) -> 13465.9 | AP7: =VLOOKUP(AJ7,$AS$5:$AX$52,6,FALSE) -> 13983.4 | AS7: 44986 | AT7: 12375.7 | AU7: 0 | AV7: 0 | AW7: 0 | AX7: 0
E8: ="Média de geração diária de eletricidade em "&YEAR(Y3)&"" -> Média de geração diária de eletricidade em 2026 | F8: =IFERROR(HLOOKUP("Total",'USINA 01 - Barreirinhas'!$CI$4:$CU$8,5),0) -> 397.06737 | G8: =IFERROR(HLOOKUP("Total",'USINA 02 - Barreirinhas'!$CI$4:$CU$8,5),0) -> 442.21474 | H8: =IFERROR(HLOOKUP("Total",'USINA 03 - Barreirinhas'!$CI$4:$CU$8,5),0) -> 396.9 | I8: =IFERROR(HLOOKUP("Total",'USINA 05 - Barreirinhas'!$CI$4:$CU$8,5),0) -> 416.41684 | J8: =IFERROR(HLOOKUP("Total",'USINA 06 - Barreirinhas'!$CI$4:$CU$8,5),0) -> 446.86737 | K8: - | AD8: =MAX(F8:J8) -> 446.86737 | AH8: =AH7+1 -> 3 | AI8: =AI9-31 -> 45846 | AJ8: =AK8 -> 45809 | AK8: =EOMONTH(AI8,-2)+1 -> 45809 | AL8: =VLOOKUP(AJ8,$AS$5:$AX$52,2,FALSE) -> 14774.8 | AM8: =VLOOKUP(AJ8,$AS$5:$AX$52,3,FALSE) -> 14505.4 | AN8: =VLOOKUP(AJ8,$AS$5:$AX$52,4,FALSE) -> 14028 | AO8: =VLOOKUP(AJ8,$AS$5:$AX$52,5,FALSE) -> 13432.5 | AP8: =VLOOKUP(AJ8,$AS$5:$AX$52,6,FALSE) -> 14000.9 | AS8: 45017 | AT8: 6248.2 | AU8: 0 | AV8: 0 | AW8: 0 | AX8: 0
E9: ="Projeção geração mensal - base na média diária em "&YEAR(Y3)&"" -> Projeção geração mensal - base na média diária em 2026 | F9: =F8*365/12 -> 12077.466 | G9: =G8*365/12 -> 13450.698 | H9: =H8*365/12 -> 12072.375 | I9: =I8*365/12 -> 12666.012 | J9: =J8*365/12 -> 13592.216 | K9: - | AD9: =MAX(F10:J10) -> 597.2 | AH9: =AH8+1 -> 4 | AI9: =AI10-31 -> 45877 | AJ9: =AK9 -> 45839 | AK9: =EOMONTH(AI9,-2)+1 -> 45839 | AL9: =VLOOKUP(AJ9,$AS$5:$AX$52,2,FALSE) -> 15755.8 | AM9: =VLOOKUP(AJ9,$AS$5:$AX$52,3,FALSE) -> 15599.2 | AN9: =VLOOKUP(AJ9,$AS$5:$AX$52,4,FALSE) -> 15266.3 | AO9: =VLOOKUP(AJ9,$AS$5:$AX$52,5,FALSE) -> 14770.5 | AP9: =VLOOKUP(AJ9,$AS$5:$AX$52,6,FALSE) -> 15145 | AS9: 45047 | AT9: 14201.9 | AU9: 0 | AV9: 0 | AW9: 0 | AX9: 0
E10: ="Geração máxima em "&YEAR(Y3)&"" -> Geração máxima em 2026 | F10: ='USINA 01 - Barreirinhas'!$CU$9 -> 596 | G10: ='USINA 02 - Barreirinhas'!$CU$9 -> 597.2 | H10: ='USINA 03 - Barreirinhas'!$CU$9 -> 563.6 | I10: ='USINA 05 - Barreirinhas'!$CU$9 -> 557.2 | J10: ='USINA 06 - Barreirinhas'!$CU$9 -> 580.7 | K10: - | AD10: =MAX(F11:J11) -> 0.76953223 | AH10: =AH9+1 -> 5 | AI10: =AI11-31 -> 45908 | AJ10: =AK10 -> 45870 | AK10: =EOMONTH(AI10,-2)+1 -> 45870 | AL10: =VLOOKUP(AJ10,$AS$5:$AX$52,2,FALSE) -> 16483.5 | AM10: =VLOOKUP(AJ10,$AS$5:$AX$52,3,FALSE) -> 16530.7 | AN10: =VLOOKUP(AJ10,$AS$5:$AX$52,4,FALSE) -> 16201.8 | AO10: =VLOOKUP(AJ10,$AS$5:$AX$52,5,FALSE) -> 15617.2 | AP10: =VLOOKUP(AJ10,$AS$5:$AX$52,6,FALSE) -> 16076 | AS10: 45078 | AT10: 12993.9 | AU10: 0 | AV10: 0 | AW10: 0 | AX10: 0
E11: ="Média Diária vs Geração Máxima em "&YEAR(Y3)&"" -> Média Diária vs Geração Máxima em 2026 | F11: =IFERROR(F8/F10,0) -> 0.66622042 | G11: =IFERROR(G8/G10,0) -> 0.74048014 | H11: =IFERROR(H8/H10,0) -> 0.70422285 | I11: =IFERROR(I8/I10,0) -> 0.74733819 | J11: =IFERROR(J8/J10,0) -> 0.76953223 | K11: - | AH11: =AH10+1 -> 6 | AI11: =AI12-31 -> 45939 | AJ11: =AK11 -> 45901 | AK11: =EOMONTH(AI11,-2)+1 -> 45901 | AL11: =VLOOKUP(AJ11,$AS$5:$AX$52,2,FALSE) -> 16424.3 | AM11: =VLOOKUP(AJ11,$AS$5:$AX$52,3,FALSE) -> 16429.6 | AN11: =VLOOKUP(AJ11,$AS$5:$AX$52,4,FALSE) -> 16582.6 | AO11: =VLOOKUP(AJ11,$AS$5:$AX$52,5,FALSE) -> 16211.3 | AP11: =VLOOKUP(AJ11,$AS$5:$AX$52,6,FALSE) -> 16579.1 | AS11: 45108 | AT11: 16526.8 | AU11: 0 | AV11: 0 | AW11: 0 | AX11: 0
AH12: =AH11+1 -> 7 | AI12: =AI13-30 -> 45970 | AJ12: =AK12 -> 45931 | AK12: =EOMONTH(AI12,-2)+1 -> 45931 | AL12: =VLOOKUP(AJ12,$AS$5:$AX$52,2,FALSE) -> 16177.7 | AM12: =VLOOKUP(AJ12,$AS$5:$AX$52,3,FALSE) -> 17094.7 | AN12: =VLOOKUP(AJ12,$AS$5:$AX$52,4,FALSE) -> 16965.5 | AO12: =VLOOKUP(AJ12,$AS$5:$AX$52,5,FALSE) -> 14770.3 | AP12: =VLOOKUP(AJ12,$AS$5:$AX$52,6,FALSE) -> 17024.5 | AS12: 45139 | AT12: 16609.9 | AU12: 0 | AV12: 0 | AW12: 0 | AX12: 0
E13: Geração diária - últimos 7 dias | AH13: =AH12+1 -> 8 | AI13: =AI14-30 -> 46000 | AJ13: =AK13 -> 45962 | AK13: =EOMONTH(AI13,-2)+1 -> 45962 | AL13: =VLOOKUP(AJ13,$AS$5:$AX$52,2,FALSE) -> 14812.7 | AM13: =VLOOKUP(AJ13,$AS$5:$AX$52,3,FALSE) -> 15617 | AN13: =VLOOKUP(AJ13,$AS$5:$AX$52,4,FALSE) -> 15411.9 | AO13: =VLOOKUP(AJ13,$AS$5:$AX$52,5,FALSE) -> 14940.3 | AP13: =VLOOKUP(AJ13,$AS$5:$AX$52,6,FALSE) -> 15410.4 | AS13: 45170 | AT13: 7504.1 | AU13: 0 | AV13: 0 | AW13: 0 | AX13: 0
E14: Dia | F14: =F4 -> SPE 1 | G14: =G4 -> SPE 2 | H14: =H4 -> SPE 3 | I14: =I4 -> SPE 5 | J14: =J4 -> SPE 6 | K14: %∆ Máx e Mín | AD14: Máxima - Geração diária - últimos 7 dias | AE14: Mínimo - Geração diária - últimos 7 dias | AH14: =AH13+1 -> 9 | AI14: =AI15-30 -> 46030 | AJ14: =AK14 -> 45992 | AK14: =EOMONTH(AI14,-2)+1 -> 45992 | AL14: =VLOOKUP(AJ14,$AS$5:$AX$52,2,FALSE) -> 11194.7 | AM14: =VLOOKUP(AJ14,$AS$5:$AX$52,3,FALSE) -> 13793 | AN14: =VLOOKUP(AJ14,$AS$5:$AX$52,4,FALSE) -> 13346 | AO14: =VLOOKUP(AJ14,$AS$5:$AX$52,5,FALSE) -> 13002.1 | AP14: =VLOOKUP(AJ14,$AS$5:$AX$52,6,FALSE) -> 12670 | AS14: 45200 | AT14: 9262.6 | AU14: 0 | AV14: 0 | AW14: 0 | AX14: 0
E15: =Y3-1 -> 46117 | F15: =VLOOKUP(E15,'USINA 01 - Barreirinhas'!$BZ$4:$CA$378,2) -> 415.9 | G15: =VLOOKUP(E15,'USINA 02 - Barreirinhas'!$BZ$4:$CA$378,2) -> 416.4 | H15: =VLOOKUP(E15,'USINA 03 - Barreirinhas'!$BZ$4:$CA$378,2) -> 0 | I15: =VLOOKUP(E15,'USINA 05 - Barreirinhas'!$BZ$4:$CA$378,2) -> 380.2 | J15: =VLOOKUP(E15,'USINA 06 - Barreirinhas'!$BZ$4:$CA$378,2) -> 422.8 | K15: =1-(SMALL(F15:J15,COUNTIF(F15:J15,"0")+1))/(MAX(F15:J15)) -> 0.10075686 | AD15: =MAX(F15:J15) -> 422.8 | AE15: =(SMALL(F15:J15,COUNTIF(F15:J15,"0")+1)) -> 380.2 | AH15: =AH14+1 -> 10 | AI15: =AI16-30 -> 46060 | AJ15: =AK15 -> 46023 | AK15: =EOMONTH(AI15,-2)+1 -> 46023 | AL15: =VLOOKUP(AJ15,$AS$5:$AX$52,2,FALSE) -> 12203.2 | AM15: =VLOOKUP(AJ15,$AS$5:$AX$52,3,FALSE) -> 14337.7 | AN15: =VLOOKUP(AJ15,$AS$5:$AX$52,4,FALSE) -> 14478 | AO15: =VLOOKUP(AJ15,$AS$5:$AX$52,5,FALSE) -> 13793.4 | AP15: =VLOOKUP(AJ15,$AS$5:$AX$52,6,FALSE) -> 14865.4 | AS15: 45231 | AT15: 12940.1 | AU15: 0 | AV15: 0 | AW15: 0 | AX15: 0
E16: =E15-1 -> 46116 | F16: =VLOOKUP(E16,'USINA 01 - Barreirinhas'!$BZ$4:$CA$378,2) -> 531.3 | G16: =VLOOKUP(E16,'USINA 02 - Barreirinhas'!$BZ$4:$CA$378,2) -> 525.2 | H16: =VLOOKUP(E16,'USINA 03 - Barreirinhas'!$BZ$4:$CA$378,2) -> 0 | I16: =VLOOKUP(E16,'USINA 05 - Barreirinhas'!$BZ$4:$CA$378,2) -> 442.2 | J16: =VLOOKUP(E16,'USINA 06 - Barreirinhas'!$BZ$4:$CA$378,2) -> 507.6 | K16: =1-(SMALL(F16:J16,COUNTIF(F16:J16,"0")+1))/(MAX(F16:J16)) -> 0.16770186 | AD16: =MAX(F16:J16) -> 531.3 | AE16: =(SMALL(F16:J16,COUNTIF(F16:J16,"0")+1)) -> 442.2 | AH16: =AH15+1 -> 11 | AI16: =AI17-28 -> 46090 | AJ16: =AK16 -> 46054 | AK16: =EOMONTH(AI16,-2)+1 -> 46054 | AL16: =VLOOKUP(AJ16,$AS$5:$AX$52,2,FALSE) -> 12332.2 | AM16: =VLOOKUP(AJ16,$AS$5:$AX$52,3,FALSE) -> 12753 | AN16: =VLOOKUP(AJ16,$AS$5:$AX$52,4,FALSE) -> 12128.8 | AO16: =VLOOKUP(AJ16,$AS$5:$AX$52,5,FALSE) -> 11994.5 | AP16: =VLOOKUP(AJ16,$AS$5:$AX$52,6,FALSE) -> 12822.6 | AS16: 45261 | AT16: 11226.6 | AU16: 0 | AV16: 0 | AW16: 0 | AX16: 0
E17: =E16-1 -> 46115 | F17: =VLOOKUP(E17,'USINA 01 - Barreirinhas'!$BZ$4:$CA$378,2) -> 517.5 | G17: =VLOOKUP(E17,'USINA 02 - Barreirinhas'!$BZ$4:$CA$378,2) -> 513.1 | H17: =VLOOKUP(E17,'USINA 03 - Barreirinhas'!$BZ$4:$CA$378,2) -> 0 | I17: =VLOOKUP(E17,'USINA 05 - Barreirinhas'!$BZ$4:$CA$378,2) -> 498.9 | J17: =VLOOKUP(E17,'USINA 06 - Barreirinhas'!$BZ$4:$CA$378,2) -> 527.1 | K17: =1-(SMALL(F17:J17,COUNTIF(F17:J17,"0")+1))/(MAX(F17:J17)) -> 0.053500285 | AD17: =MAX(F17:J17) -> 527.1 | AE17: =(SMALL(F17:J17,COUNTIF(F17:J17,"0")+1)) -> 498.9 | AH17: =AH16+1 -> 12 | AI17: =Z3 -> 46118 | AJ17: =AK17 -> 46082 | AK17: =EOMONTH(AI17,-2)+1 -> 46082 | AL17: =VLOOKUP(AJ17,$AS$5:$AX$52,2,FALSE) -> 11132.2 | AM17: =VLOOKUP(AJ17,$AS$5:$AX$52,3,FALSE) -> 12856.3 | AN17: =VLOOKUP(AJ17,$AS$5:$AX$52,4,FALSE) -> 11098.7 | AO17: =VLOOKUP(AJ17,$AS$5:$AX$52,5,FALSE) -> 11883.6 | AP17: =VLOOKUP(AJ17,$AS$5:$AX$52,6,FALSE) -> 12704.3 | AS17: 45292 | AT17: {=TRANSPOSE('USINA 01 - Barreirinhas'!AH6:AS6)} -> 12403.7 | AU17: {=TRANSPOSE('USINA 02 - Barreirinhas'!AH6:AS6)} -> 11968.3 | AV17: {=TRANSPOSE('USINA 03 - Barreirinhas'!AH6:AS6)} -> 0 | AW17: {=TRANSPOSE('USINA 05 - Barreirinhas'!AH6:AS6)} -> 7762.6 | AX17: {=TRANSPOSE('USINA 06 - Barreirinhas'!AH6:AS6)} -> 10832
E18: =E17-1 -> 46114 | F18: =VLOOKUP(E18,'USINA 01 - Barreirinhas'!$BZ$4:$CA$378,2) -> 267.7 | G18: =VLOOKUP(E18,'USINA 02 - Barreirinhas'!$BZ$4:$CA$378,2) -> 277.5 | H18: =VLOOKUP(E18,'USINA 03 - Barreirinhas'!$BZ$4:$CA$378,2) -> 0 | I18: =VLOOKUP(E18,'USINA 05 - Barreirinhas'!$BZ$4:$CA$378,2) -> 247.5 | J18: =VLOOKUP(E18,'USINA 06 - Barreirinhas'!$BZ$4:$CA$378,2) -> 260.5 | K18: =1-(SMALL(F18:J18,COUNTIF(F18:J18,"0")+1))/(MAX(F18:J18)) -> 0.10810811 | AD18: =MAX(F18:J18) -> 277.5 | AE18: =(SMALL(F18:J18,COUNTIF(F18:J18,"0")+1)) -> 247.5 | AI18: =AI17+31 -> 46149 | AJ18: =AK18 -> 46113 | AK18: =EOMONTH(AI18,-2)+1 -> 46113 | AS18: 45323 | AT18: 11324.1 | AU18: 11816 | AV18: 0 | AW18: 11108.2 | AX18: 11750.3
E19: =E18-1 -> 46113 | F19: =VLOOKUP(E19,'USINA 01 - Barreirinhas'!$BZ$4:$CA$378,2) -> 321.4 | G19: =VLOOKUP(E19,'USINA 02 - Barreirinhas'!$BZ$4:$CA$378,2) -> 331.2 | H19: =VLOOKUP(E19,'USINA 03 - Barreirinhas'!$BZ$4:$CA$378,2) -> 0 | I19: =VLOOKUP(E19,'USINA 05 - Barreirinhas'!$BZ$4:$CA$378,2) -> 319.3 | J19: =VLOOKUP(E19,'USINA 06 - Barreirinhas'!$BZ$4:$CA$378,2) -> 341.9 | K19: =1-(SMALL(F19:J19,COUNTIF(F19:J19,"0")+1))/(MAX(F19:J19)) -> 0.066101199 | AD19: =MAX(F19:J19) -> 341.9 | AE19: =(SMALL(F19:J19,COUNTIF(F19:J19,"0")+1)) -> 319.3 | AI19: =AI18+31 -> 46180 | AJ19: =AK19 -> 46143 | AK19: =EOMONTH(AI19,-2)+1 -> 46143 | AS19: 45352 | AT19: 12777.9 | AU19: 13142.6 | AV19: 0 | AW19: 12184.2 | AX19: 12798.1
E20: =E19-1 -> 46112 | F20: =VLOOKUP(E20,'USINA 01 - Barreirinhas'!$BZ$4:$CA$378,2) -> 596 | G20: =VLOOKUP(E20,'USINA 02 - Barreirinhas'!$BZ$4:$CA$378,2) -> 597.2 | H20: =VLOOKUP(E20,'USINA 03 - Barreirinhas'!$BZ$4:$CA$378,2) -> 0 | I20: =VLOOKUP(E20,'USINA 05 - Barreirinhas'!$BZ$4:$CA$378,2) -> 501.2 | J20: =VLOOKUP(E20,'USINA 06 - Barreirinhas'!$BZ$4:$CA$378,2) -> 580.7 | K20: =1-(SMALL(F20:J20,COUNTIF(F20:J20,"0")+1))/(MAX(F20:J20)) -> 0.16075017 | AD20: =MAX(F20:J20) -> 597.2 | AE20: =(SMALL(F20:J20,COUNTIF(F20:J20,"0")+1)) -> 501.2 | AI20: =AI19+31 -> 46211 | AJ20: =AK20 -> 46174 | AK20: =EOMONTH(AI20,-2)+1 -> 46174 | AS20: 45383 | AT20: 12706.2 | AU20: 12696.7 | AV20: 0 | AW20: 11092.4 | AX20: 10541.4
E21: =E20-1 -> 46111 | F21: =VLOOKUP(E21,'USINA 01 - Barreirinhas'!$BZ$4:$CA$378,2) -> 349.3 | G21: =VLOOKUP(E21,'USINA 02 - Barreirinhas'!$BZ$4:$CA$378,2) -> 380.7 | H21: =VLOOKUP(E21,'USINA 03 - Barreirinhas'!$BZ$4:$CA$378,2) -> 211.9 | I21: =VLOOKUP(E21,'USINA 05 - Barreirinhas'!$BZ$4:$CA$378,2) -> 313.2 | J21: =VLOOKUP(E21,'USINA 06 - Barreirinhas'!$BZ$4:$CA$378,2) -> 346.6 | K21: =1-(SMALL(F21:J21,COUNTIF(F21:J21,"0")+1))/(MAX(F21:J21)) -> 0.44339375 | AD21: =MAX(F21:J21) -> 380.7 | AE21: =(SMALL(F21:J21,COUNTIF(F21:J21,"0")+1)) -> 211.9 | AI21: =AI20+31 -> 46242 | AJ21: =AK21 -> 46204 | AK21: =EOMONTH(AI21,-2)+1 -> 46204 | AS21: 45413 | AT21: 14754.5 | AU21: 14678.8 | AV21: 0 | AW21: 14108.3 | AX21: 11445.1
AI22: =AI21+31 -> 46273 | AJ22: =AK22 -> 46235 | AK22: =EOMONTH(AI22,-2)+1 -> 46235 | AS22: 45444 | AT22: 10264.9 | AU22: 14329.2 | AV22: 0 | AW22: 9513.2 | AX22: 10905
AI23: =AI22+31 -> 46304 | AJ23: =AK23 -> 46266 | AK23: =EOMONTH(AI23,-2)+1 -> 46266 | AS23: 45474 | AT23: 16180.8 | AU23: 16065.3 | AV23: 0 | AW23: 15155.8 | AX23: 12151
AI24: =AI23+31 -> 46335 | AJ24: =AK24 -> 46296 | AK24: =EOMONTH(AI24,-2)+1 -> 46296 | AS24: 45505 | AT24: 14513.9 | AU24: 17159.6 | AV24: 4407.3 | AW24: 12545.7 | AX24: 13183.9
AI25: =AI24+31 -> 46366 | AJ25: =AK25 -> 46327 | AK25: =EOMONTH(AI25,-2)+1 -> 46327 | AS25: 45536 | AT25: 16702.3 | AU25: 16824 | AV25: 17100.4 | AW25: 16731.6 | AX25: 13320.2
AI26: =AI25+31 -> 46397 | AJ26: =AK26 -> 46357 | AK26: =EOMONTH(AI26,-2)+1 -> 46357 | AS26: 45566 | AT26: 15717.8 | AU26: 15913.8 | AV26: 16410.1 | AW26: 15900.4 | AX26: 12852.2
AI27: =AI26+31 -> 46428 | AJ27: =AK27 -> 46388 | AK27: =EOMONTH(AI27,-2)+1 -> 46388 | AS27: 45597 | AT27: 13932.6 | AU27: 12892.7 | AV27: 15260.1 | AW27: 14660.8 | AX27: 14715.5
AI28: =AI27+31 -> 46459 | AJ28: =AK28 -> 46419 | AK28: =EOMONTH(AI28,-2)+1 -> 46419 | AS28: 45627 | AT28: 11859.7 | AU28: 12577.5 | AV28: 14864.2 | AW28: 14109.7 | AX28: 14744.9
AI29: =AI28+31 -> 46490 | AJ29: =AK29 -> 46447 | AK29: =EOMONTH(AI29,-2)+1 -> 46447 | AS29: 45658 | AT29: {=TRANSPOSE('USINA 01 - Barreirinhas'!BG6:BR6)} -> 9089.5 | AU29: {=TRANSPOSE('USINA 02 - Barreirinhas'!BG6:BR6)} -> 13186.3 | AV29: {=TRANSPOSE('USINA 03 - Barreirinhas'!BG6:BR6)} -> 12706 | AW29: {=TRANSPOSE('USINA 05 - Barreirinhas'!BG6:BR6)} -> 12280.4 | AX29: {=TRANSPOSE('USINA 06 - Barreirinhas'!BG6:BR6)} -> 12724.7
X30: Potencial de geração das usinas solares (kWh) | AI30: =AI29+31 -> 46521 | AJ30: =AK30 -> 46478 | AK30: =EOMONTH(AI30,-2)+1 -> 46478 | AS30: 45689 | AT30: 9027.6 | AU30: 10613.1 | AV30: 10575.3 | AW30: 10108.7 | AX30: 10723.3
X31: Descrição | Y31: Valor | Z31: Mínimo | AA31: Máximo | AI31: =AI30+31 -> 46552 | AJ31: =AK31 -> 46508 | AK31: =EOMONTH(AI31,-2)+1 -> 46508 | AS31: 45717 | AT31: 8751 | AU31: 13530.6 | AV31: 12895 | AW31: 12438.5 | AX31: 13122.9
X32: Mês | Y32: 14000 | Z32: =Y32*0.85 -> 11900 | AA32: =Y32*1.15 -> 16100 | AI32: =AI31+31 -> 46583 | AJ32: =AK32 -> 46539 | AK32: =EOMONTH(AI32,-2)+1 -> 46539 | AS32: 45748 | AT32: 13720.3 | AU32: 13883.2 | AV32: 11937.5 | AW32: 11535.9 | AX32: 13580.7
X33: Ano | Y33: =Y32*12 -> 168000 | Z33: =Y33*0.85 -> 142800 | AA33: =Y33*1.15 -> 193200 | AI33: =AI32+31 -> 46614 | AJ33: =AK33 -> 46569 | AK33: =EOMONTH(AI33,-2)+1 -> 46569 | AS33: 45778 | AT33: 14433.7 | AU33: 14553.5 | AV33: 14278 | AW33: 13465.9 | AX33: 13983.4
AI34: =AI33+31 -> 46645 | AJ34: =AK34 -> 46600 | AK34: =EOMONTH(AI34,-2)+1 -> 46600 | AS34: 45809 | AT34: 14774.8 | AU34: 14505.4 | AV34: 14028 | AW34: 13432.5 | AX34: 14000.9
X35: Geração mínima (kWh) | Z35: =Z32/30 -> 396.66667 | AI35: =AI34+31 -> 46676 | AJ35: =AK35 -> 46631 | AK35: =EOMONTH(AI35,-2)+1 -> 46631 | AS35: 45839 | AT35: 15755.8 | AU35: 15599.2 | AV35: 15266.3 | AW35: 14770.5 | AX35: 15145
AI36: =AI35+31 -> 46707 | AJ36: =AK36 -> 46661 | AK36: =EOMONTH(AI36,-2)+1 -> 46661 | AS36: 45870 | AT36: 16483.5 | AU36: 16530.7 | AV36: 16201.8 | AW36: 15617.2 | AX36: 16076
AI37: =AI36+31 -> 46738 | AJ37: =AK37 -> 46692 | AK37: =EOMONTH(AI37,-2)+1 -> 46692 | AS37: 45901 | AT37: 16424.3 | AU37: 16429.6 | AV37: 16582.6 | AW37: 16211.3 | AX37: 16579.1
AI38: =AI37+31 -> 46769 | AJ38: =AK38 -> 46722 | AK38: =EOMONTH(AI38,-2)+1 -> 46722 | AS38: 45931 | AT38: 16177.7 | AU38: 17094.7 | AV38: 16965.5 | AW38: 14770.3 | AX38: 17024.5
AI39: =AI38+31 -> 46800 | AJ39: =AK39 -> 46753 | AK39: =EOMONTH(AI39,-2)+1 -> 46753 | AS39: 45962 | AT39: 14812.7 | AU39: 15617 | AV39: 15411.9 | AW39: 14940.3 | AX39: 15410.4
AI40: =AI39+31 -> 46831 | AJ40: =AK40 -> 46813 | AK40: =EOMONTH(AI40,-2)+30 -> 46813 | AS40: 45992 | AT40: 11194.7 | AU40: 13793 | AV40: 13346 | AW40: 13002.1 | AX40: 12670
...

Sheet USINA 01 - Barreirinhas
A2: Histórico de geração - SPE 1 (2023) | Y2: Histórico de geração - SPE 1 (2024) | AX2: Histórico de geração - SPE 1 (2025) | BZ2: Histórico de geração - SPE 1 (2026)
A3: Dia | B3: Geração de energia diária (inversor)(kWh) | C3: Período Equatorial | D3: Referência | E3: A | F3: B | Y3: Dia | Z3: Geração de energia diária (inversor)(kWh) | AA3: Sem medição | AB3: Período Equatorial | AC3: Referência | AD3: A | AE3: B | AM3: =24/30 -> 0.8 | AN3: =AM3*AL6 -> 11803.6 | AX3: Dia | AY3: Geração de energia diária (inversor)(kWh) | AZ3: Dias sem gesração | BA3: Período Equatorial | BB3: Referência | BC3: A | BD3: B | BZ3: Dia | CA3: Geração de energia diária (inversor)(kWh) | CB3: Dias sem gesração | CC3: Período Equatorial | CD3: Referência | CE3: A | CF3: B
A4: 44927 | B4: 0 | C4: =IFERROR(VLOOKUP(A3,$H$381:$N$415,5,FALSE),"") | D4: 44896 | E4: =IFERROR(VLOOKUP(A4,$H$422:$J$433,3,FALSE),"") -> 44927 | F4: 44927 | H4: Descrição | I4: 44927 | J4: 44958 | K4: 44986 | L4: 45017 | M4: 45047 | N4: 45078 | O4: 45108 | P4: 45139 | Q4: 45170 | R4: 45200 | S4: 45231 | T4: 45261 | U4: Total | Y4: =A364 -> 45287 | AB4: 45261 | AC4: 45261 | AD4: =IFERROR(VLOOKUP(Y4,$H$422:$J$457,3,FALSE),"") | AG4: Descrição | AH4: 45292 | AI4: 45323 | AJ4: 45352 | AK4: 45383 | AL4: 45413 | AM4: 45444 | AN4: 45474 | AO4: 45505 | AP4: 45536 | AQ4: 45566 | AR4: 45597 | AS4: 45627 | AT4: Total | AX4: =Y364 -> 45647 | AY4: 464.4 | AZ4: =IF(AY4=0,1,0) -> 0 | BA4: =IFERROR(VLOOKUP(AX3,'Geração Equatorial x Medido'!$O$4:$P$55,2,FALSE),"") | BB4: 45627 | BC4: =IFERROR(VLOOKUP(AX4,$H$422:$J$457,3,FALSE),"") | BF4: Descrição | BG4: 45658 | BH4: 45689 | BI4: 45717 | BJ4: 45748 | BK4: 45778 | BL4: 45809 | BM4: 45839 | BN4: 45870 | BO4: 45901 | BP4: 45931 | BQ4: 45962 | BR4: 45992 | BS4: Total | BZ4: =AX369+1 -> 46013 | CA4: =AY370 -> 153.7 | CB4: =IF(CA4=0,1,0) -> 0 | CC4: =IFERROR(VLOOKUP(BZ3,'Geração Equatorial x Medido'!$O$4:$P$55,2,FALSE),"") | CD4: 45992 | CE4: =IFERROR(VLOOKUP(BZ4,$H$422:$J$469,3,FALSE),"") | CH4: Descrição | CI4: 46023 | CJ4: 46054 | CK4: 46082 | CL4: 46113 | CM4: 46143 | CN4: 46174 | CO4: 46204 | CP4: 46235 | CQ4: 46266 | CR4: 46296 | CS4: 46327 | CT4: 46357 | CU4: Total
A5: =A4+1 -> 44928 | B5: 0 | C5: =IFERROR(VLOOKUP(A5,'Geração Equatorial x Medido'!$O$4:$P$15,2,FALSE),"") | D5: =IF(C5="",D4,C5) -> 44896 | E5: =IFERROR(VLOOKUP(A5,$H$422:$J$433,3,FALSE),"") | F5: =IF(E5="",F4,E5) -> 44927 | H5: Somado da tabela (kWh) | I5: =SUMIF($F:$F,I4,$B:$B) -> 0 | J5: =SUMIF($F:$F,J4,$B:$B) -> 10149.7 | K5: =SUMIF($F:$F,K4,$B:$B) -> 12375.7 | L5: =SUMIF($F:$F,L4,$B:$B) -> 6248.2 | M5: =SUMIF($F:$F,M4,$B:$B) -> 14201.9 | N5: =SUMIF($F:$F,N4,$B:$B) -> 12993.9 | O5: =SUMIF($F:$F,O4,$B:$B) -> 16526.8 | P5: =SUMIF($F:$F,P4,$B:$B) -> 16609.9 | ... T5: =SUMIF($F:$F,T4,$B:$B) -> 11226.6 | U5: =SUM($I$5:$T$5) -> 130338.8 | Y5: =Y4+1 -> 45288 | AB5: =IFERROR(VLOOKUP(Y5,'Geração Equatorial x Medido'!$O$15:$R$18,2,FALSE),"") -> 45261 | AC5: =IF(AB5="",AC4,AB5) -> 45261 | AD5: =IFERROR(VLOOKUP(Y5,$H$422:$J$457,3,FALSE),"") | AG5: Somado da tabela (kWh) | AH5: =SUMIF($AE:$AE,AH4,$Z:$Z) -> 12403.7 | AI5: =SUMIF($AE:$AE,AI4,$Z:$Z) -> 11324.1 | AJ5: =SUMIF($AE:$AE,AJ4,$Z:$Z) -> 12777.9 | AK5: =SUMIF($AE:$AE,AK4,$Z:$Z) -> 12706.2 | AL5: =SUMIF($AE:$AE,AL4,$Z:$Z) -> 14754.5 | AM5: =SUMIF($AE:$AE,AM4,$Z:$Z) -> 10264.9 | AN5: =SUMIF($AE:$AE,AN4,$Z:$Z) -> 16180.8 | AO5: =SUMIF($AE:$AE,AO4,$Z:$Z) -> 14513.9 | ... AS5: =SUMIF($AE:$AE,AS4,$Z:$Z) -> 11859.7 | AT5: =SUM(AH5:AS5) -> 163138.4 | AU5: =AT5/12 -> 13594.867 | AX5: =AX4+1 -> 45648 | AY5: 209.8 | AZ5: =IF(AY5=0,1,0) -> 0 | BA5: =IFERROR(VLOOKUP(AX4,'Geração Equatorial x Medido'!$O$4:$P$55,2,FALSE),"") | BB5: =IF(BA5="",BB4,BA5) -> 45627 | BC5: =IFERROR(VLOOKUP(AX5,$H$422:$J$457,3,FALSE),"") | BF5: Somado da tabela (kWh) | BG5: =SUMIF($BD:$BD,BG4,$AY:$AY) -> 9089.5 | BH5: =SUMIF($BD:$BD,BH4,$AY:$AY) -> 9027.6 | BI5: =SUMIF($BD:$BD,BI4,$AY:$AY) -> 8751 | BJ5: =SUMIF($BD:$BD,BJ4,$AY:$AY) -> 13720.3 | BK5: =SUMIF($BD:$BD,BK4,$AY:$AY) -> 14433.7 | BL5: =SUMIF($BD:$BD,BL4,$AY:$AY) -> 14774.8 | BM5: =SUMIF($BD:$BD,BM4,$AY:$AY) -> 15755.8 | BN5: =SUMIF($BD:$BD,BN4,$AY:$AY) -> 16483.5 | ... BR5: =SUMIF($BD:$BD,BR4,$AY:$AY) -> 11194.7 | BS5: =SUM(BG5:BR5) -> 160645.6 | BZ5: =BZ4+1 -> 46014 | CA5: =AY371 -> 435.7 | CB5: =IF(CA5=0,1,0) -> 0 | CC5: =IFERROR(VLOOKUP(BZ4,'Geração Equatorial x Medido'!$O$4:$P$55,2,FALSE),"") | CD5: =IF(CC5="",CD4,CC5) -> 45992 | CE5: =IFERROR(VLOOKUP(BZ5,$H$422:$J$469,3,FALSE),"") | CH5: Somado da tabela (kWh) | CI5: =SUMIF($CF:$CF,CI4,$CA:$CA) -> 12203.2 | CJ5: =SUMIF($CF:$CF,CJ4,$CA:$CA) -> 12332.2 | CK5: =SUMIF($CF:$CF,CK4,$CA:$CA) -> 11132.2 | CL5: =SUMIF($CF:$CF,CL4,$CA:$CA) -> 2053.8 | CM5: =SUMIF($CF:$CF,CM4,$CA:$CA) -> 0 | CN5: =SUMIF($CF:$CF,CN4,$CA:$CA) -> 0 | CO5: =SUMIF($CF:$CF,CO4,$CA:$CA) -> 0 | CP5: =SUMIF($CF:$CF,CP4,$CA:$CA) -> 0 | ... CT5: =SUMIF($CF:$CF,CT4,$CA:$CA) -> 0 | CU5: =SUM(CI5:CT5) -> 37721.4
A6: =A5+1 -> 44929 | B6: 0 | C6: =IFERROR(VLOOKUP(A6,'Geração Equatorial x Medido'!$O$4:$P$15,2,FALSE),"") | D6: =IF(C6="",D5,C6) -> 44896 | E6: =IFERROR(VLOOKUP(A6,$H$422:$J$433,3,FALSE),"") | F6: =IF(E6="",F5,E6) -> 44927 | H6: Supervisório (kWh) | I6: 0 | J6: 10149.7 | K6: 12375.7 | L6: 6248.2 | M6: 14201.9 | N6: 12993.9 | O6: 16526.8 | P6: 16609.9 | Q6: 7504.1 | R6: 9262.6 | S6: 12940.1 | T6: 11226.6 | U6: =SUM(I6:T6) -> 130039.5 | Y6: =Y5+1 -> 45289 | AB6: =IFERROR(VLOOKUP(Y6,'Geração Equatorial x Medido'!$O$15:$R$18,2,FALSE),"") | AC6: =IF(AB6="",AC5,AB6) -> 45261 | AD6: =IFERROR(VLOOKUP(Y6,$H$422:$J$457,3,FALSE),"") | AG6: Supervisório (kWh) | AH6: 12403.7 | AI6: 11324.1 | AJ6: 12777.9 | AK6: 12706.2 | AL6: 14754.5 | AM6: 10264.9 | AN6: 16180.8 | AO6: 14513.9 | AP6: 16702.3 | AQ6: 15717.8 | AR6: 13932.6 | AS6: 11859.7 | AT6: =SUM(AH6:AS6) -> 163138.4 | AX6: =AX5+1 -> 45649 | AY6: 210 | AZ6: =IF(AY6=0,1,0) -> 0 | BA6: =IFERROR(VLOOKUP(AX5,'Geração Equatorial x Medido'!$O$4:$P$55,2,FALSE),"") | BB6: =IF(BA6="",BB5,BA6) -> 45627 | BC6: =IFERROR(VLOOKUP(AX6,$H$422:$J$457,3,FALSE),"") | BF6: Supervisório (kWh) | BG6: 9089.5 | BH6: 9027.6 | BI6: 8751 | BJ6: 13720.3 | BK6: 14433.7 | BL6: 14774.8 | BM6: 15755.8 | BN6: 16483.5 | BO6: 16424.3 | BP6: 16177.7 | BQ6: 14812.7 | BR6: 11194.7 | BS6: =SUM(BG6:BR6) -> 160645.6 | BZ6: =BZ5+1 -> 46015 | CA6: =AY372 -> 491.5 | CB6: =IF(CA6=0,1,0) -> 0 | CC6: =IFERROR(VLOOKUP(BZ5,'Geração Equatorial x Medido'!$O$4:$P$55,2,FALSE),"") | CD6: =IF(CC6="",CD5,CC6) -> 45992 | CE6: =IFERROR(VLOOKUP(BZ6,$H$422:$J$469,3,FALSE),"") | CH6: Supervisório (kWh) | CI6: 12203.2 | CJ6: 12332.2 | CK6: 11132.2 | CU6: =SUM(CI6:CT6) -> 35667.6
A7: =A6+1 -> 44930 | B7: 0 | C7: =IFERROR(VLOOKUP(A7,'Geração Equatorial x Medido'!$O$4:$P$15,2,FALSE),"") | D7: =IF(C7="",D6,C7) -> 44896 | E7: =IFERROR(VLOOKUP(A7,$H$422:$J$433,3,FALSE),"") | F7: =IF(E7="",F6,E7) -> 44927 | H7: Diferença (kWh) | I7: =I5-I6 -> 0 | J7: =J5-J6 -> 0 | K7: =K5-K6 -> 0 | L7: =L5-L6 -> 0 | M7: =M5-M6 -> 0 | N7: =N5-N6 -> 0 | O7: =O5-O6 -> 0 | P7: =P5-P6 -> 0 | ... T7: =T5-T6 -> 0 | U7: =SUM(I7:T7) -> 299.3 | Y7: =Y6+1 -> 45290 | AB7: =IFERROR(VLOOKUP(Y7,'Geração Equatorial x Medido'!$O$15:$R$18,2,FALSE),"") | AC7: =IF(AB7="",AC6,AB7) -> 45261 | AD7: =IFERROR(VLOOKUP(Y7,$H$422:$J$457,3,FALSE),"") | AG7: Diferença (kWh) | AH7: =AH5-AH6 -> 0 | AI7: =AI5-AI6 -> 0 | AJ7: =AJ5-AJ6 -> 0 | AK7: =AK5-AK6 -> 0 | AL7: =AL5-AL6 -> 0 | AM7: =AM5-AM6 -> 0 | AN7: =AN5-AN6 -> 0 | AO7: =AO5-AO6 -> 0 | ... AS7: =AS5-AS6 -> 0 | AT7: =SUM(AH7:AS7) -> 0 | AX7: =AX6+1 -> 45650 | AY7: 163.4 | AZ7: =IF(AY7=0,1,0) -> 0 | BA7: =IFERROR(VLOOKUP(AX6,'Geração Equatorial x Medido'!$O$4:$P$55,2,FALSE),"") | BB7: =IF(BA7="",BB6,BA7) -> 45627 | BC7: =IFERROR(VLOOKUP(AX7,$H$422:$J$457,3,FALSE),"") | BF7: Diferença (kWh) | BG7: =BG5-BG6 -> 0 | BH7: =BH5-BH6 -> 0 | BI7: =BI5-BI6 -> 0 | BJ7: =BJ5-BJ6 -> 0 | BK7: =BK5-BK6 -> 0 | BL7: =BL5-BL6 -> 0 | BM7: =BM5-BM6 -> 0 | BN7: =BN5-BN6 -> 0 | ... BR7: =BR5-BR6 -> 0 | BS7: =SUM(BG7:BR7) -> 0 | BZ7: =BZ6+1 -> 46016 | CA7: =AY373 -> 185.1 | CB7: =IF(CA7=0,1,0) -> 0 | CC7: =IFERROR(VLOOKUP(BZ6,'Geração Equatorial x Medido'!$O$4:$P$55,2,FALSE),"") | CD7: =IF(CC7="",CD6,CC7) -> 45992 | CE7: =IFERROR(VLOOKUP(BZ7,$H$422:$J$469,3,FALSE),"") | CH7: Diferença (kWh) | CI7: =CI5-CI6 -> 0 | CJ7: =CJ5-CJ6 -> 0 | CK7: =CK5-CK6 -> 0 | CL7: =CL5-CL6 -> 2053.8 | CM7: =CM5-CM6 -> 0 | CN7: =CN5-CN6 -> 0 | CO7: =CO5-CO6 -> 0 | CP7: =CP5-CP6 -> 0 | ... CT7: =CT5-CT6 -> 0 | CU7: =SUM(CI7:CT7) -> 2053.8
A8: =A7+1 -> 44931 | B8: 0 | C8: =IFERROR(VLOOKUP(A8,'Geração Equatorial x Medido'!$O$4:$P$15,2,FALSE),"") | D8: =IF(C8="",D7,C8) -> 44896 | E8: =IFERROR(VLOOKUP(A8,$H$422:$J$433,3,FALSE),"") | F8: =IF(E8="",F7,E8) -> 44927 | H8: Média mensal (kWh/mês) | I8: =AVERAGEIF($F:$F,I4,$B:$B) -> 0 | J8: =AVERAGEIF($F:$F,J4,$B:$B) -> 362.48929 | K8: =AVERAGEIF($F:$F,K4,$B:$B) -> 399.21613 | L8: =AVERAGEIF($F:$F,L4,$B:$B) -> 208.27333 | M8: =AVERAGEIF($F:$F,M4,$B:$B) -> 458.12581 | N8: =AVERAGEIF($F:$F,N4,$B:$B) -> 433.13 | O8: =AVERAGEIF($F:$F,O4,$B:$B) -> 533.12258 | P8: =AVERAGEIF($F:$F,P4,$B:$B) -> 535.80323 | ... T8: =AVERAGEIF($F:$F,T4,$B:$B) -> 362.14839 | U8: =AVERAGE(B4:B368) -> 357.0926 | Y8: =Y7+1 -> 45291 | AB8: =IFERROR(VLOOKUP(Y8,'Geração Equatorial x Medido'!$O$15:$R$18,2,FALSE),"") | AC8: =IF(AB8="",AC7,AB8) -> 45261 | AD8: =IFERROR(VLOOKUP(Y8,$H$422:$J$457,3,FALSE),"") | AG8: Média diária (kWh/mês) | AH8: =AVERAGEIF($AE:$AE,AH4,$Z:$Z) -> 400.11935 | AI8: =AVERAGEIF($AE:$AE,AI4,$Z:$Z) -> 390.48621 | AJ8: =AVERAGEIF($AE:$AE,AJ4,$Z:$Z) -> 412.19032 | AK8: =AVERAGEIF($AE:$AE,AK4,$Z:$Z) -> 423.54 | AL8: =AVERAGEIF($AE:$AE,AL4,$Z:$Z) -> 475.95161 | AM8: =AVERAGEIF($AE:$AE,AM4,$Z:$Z) -> 342.16333 | AN8: =AVERAGEIF($AE:$AE,AN4,$Z:$Z) -> 521.96129 | AO8: =AVERAGEIF($AE:$AE,AO4,$Z:$Z) -> 468.19032 | ... AS8: =AVERAGEIF($AE:$AE,AS4,$Z:$Z) -> 382.57097 | AT8: =AVERAGE(Z9:Z374) -> 445.73333 | AX8: =AX7+1 -> 45651 | AY8: 199.6 | AZ8: =IF(AY8=0,1,0) -> 0 | BA8: =IFERROR(VLOOKUP(AX7,'Geração Equatorial x Medido'!$O$4:$P$55,2,FALSE),"") | BB8: =IF(BA8="",BB7,BA8) -> 45627 | BC8: =IFERROR(VLOOKUP(AX8,$H$422:$J$457,3,FALSE),"") | BF8: Média diária (kWh/mês) | BG8: =AVERAGEIF($BD:$BD,BG4,$AY:$AY) -> 293.20968 | BH8: =AVERAGEIF($BD:$BD,BH4,$AY:$AY) -> 322.41429 | BI8: =AVERAGEIF($BD:$BD,BI4,$AY:$AY) -> 282.29032 | BJ8: =AVERAGEIF($BD:$BD,BJ4,$AY:$AY) -> 457.34333 | BK8: =AVERAGEIF($BD:$BD,BK4,$AY:$AY) -> 465.60323 | BL8: =AVERAGEIF($BD:$BD,BL4,$AY:$AY) -> 492.49333 | BM8: =AVERAGEIF($BD:$BD,BM4,$AY:$AY) -> 508.25161 | BN8: =AVERAGEIF($BD:$BD,BN4,$AY:$AY) -> 531.72581 | ... BR8: =AVERAGEIF($BD:$BD,BR4,$AY:$AY) -> 361.11935 | BS8: =AVERAGE(AY15:AY379) -> 440.12493 | BZ8: =BZ7+1 -> 46017 | CA8: =AY374 -> 203.7 | CB8: =IF(CA8=0,1,0) -> 0 | CC8: =IFERROR(VLOOKUP(BZ7,'Geração Equatorial x Medido'!$O$4:$P$55,2,FALSE),"") | CD8: =IF(CC8="",CD7,CC8) -> 45992 | CE8: =IFERROR(VLOOKUP(BZ8,$H$422:$J$469,3,FALSE),"") | CH8: Média diária (kWh/mês) | CI8: =AVERAGEIF($CF:$CF,CI4,$CA:$CA) -> 393.65161 | CJ8: =AVERAGEIF($CF:$CF,CJ4,$CA:$CA) -> 440.43571 | CK8: =AVERAGEIF($CF:$CF,CK4,$CA:$CA) -> 359.10323 | CL8: =AVERAGEIF($CF:$CF,CL4,$CA:$CA) -> 410.76 | CM8: =AVERAGEIF($CF:$CF,CM4,$CA:$CA) -> #DIV/0! | CN8: =AVERAGEIF($CF:$CF,CN4,$CA:$CA) -> #DIV/0! | CO8: =AVERAGEIF($CF:$CF,CO4,$CA:$CA) -> #DIV/0! | CP8: =AVERAGEIF($CF:$CF,CP4,$CA:$CA) -> #DIV/0! | ... CT8: =AVERAGEIF($CF:$CF,CT4,$CA:$CA) -> #DIV/0! | CU8: =AVERAGE(CA14:CA378) -> 397.06737
A9: =A8+1 -> 44932 | B9: 0 | C9: =IFERROR(VLOOKUP(A9,'Geração Equatorial x Medido'!$O$4:$P$15,2,FALSE),"") | D9: =IF(C9="",D8,C9) -> 44896 | E9: =IFERROR(VLOOKUP(A9,$H$422:$J$433,3,FALSE),"") | F9: =IF(E9="",F8,E9) -> 44927 | Y9: =Y8+1 -> 45292 | Z9: 396.8 | AA9: =IF(Z9=0,1,0) -> 0 | AB9: =IFERROR(VLOOKUP(Y9,'Geração Equatorial x Medido'!$O$15:$R$18,2,FALSE),"") | AC9: =IF(AB9="",AC8,AB9) -> 45261 | AD9: =IFERROR(VLOOKUP(Y9,$H$422:$J$457,3,FALSE),"") -> 45292 | AE9: =IF(AD9="",AE8,AD9) -> 45292 | AG9: Máxima anual (kWh/mês) | AH9: =_xlfn.MAXIFS($Z$4:$Z$374,$AE$4:$AE$374,AH4) -> 529.5 | AI9: =_xlfn.MAXIFS($Z$4:$Z$374,$AE$4:$AE$374,AI4) -> 535.3 | AJ9: =_xlfn.MAXIFS($Z$4:$Z$374,$AE$4:$AE$374,AJ4) -> 587.7 | AK9: =_xlfn.MAXIFS($Z$4:$Z$374,$AE$4:$AE$374,AK4) -> 611.4 | AL9: =_xlfn.MAXIFS($Z$4:$Z$374,$AE$4:$AE$374,AL4) -> 599.9 | AM9: =_xlfn.MAXIFS($Z$4:$Z$374,$AE$4:$AE$374,AM4) -> 576.1 | AN9: =_xlfn.MAXIFS($Z$4:$Z$374,$AE$4:$AE$374,AN4) -> 594.4 | AO9: =_xlfn.MAXIFS($Z$4:$Z$374,$AE$4:$AE$374,AO4) -> 592.4 | ... AS9: =_xlfn.MAXIFS($Z$4:$Z$374,$AE$4:$AE$374,AS4) -> 519.2 | AT9: =MAX(AH9:AS9) -> 611.4 | AX9: =AX8+1 -> 45652 | AY9: 213.4 | AZ9: =IF(AY9=0,1,0) -> 0 | BA9: =IFERROR(VLOOKUP(AX8,'Geração Equatorial x Medido'!$O$4:$P$55,2,FALSE),"") | BB9: =IF(BA9="",BB8,BA9) -> 45627 | BC9: =IFERROR(VLOOKUP(AX9,$H$422:$J$457,3,FALSE),"") | BF9: Máxima anual (kWh/mês) | BG9: =_xlfn.MAXIFS($AY$4:$AY$379,$BD$4:$BD$379,BG4) -> 467.2 | BH9: =_xlfn.MAXIFS($AY$4:$AY$379,$BD$4:$BD$379,BH4) -> 494.9 | BI9: =_xlfn.MAXIFS($AY$4:$AY$379,$BD$4:$BD$379,BI4) -> 561.6 | BJ9: =_xlfn.MAXIFS($AY$4:$AY$379,$BD$4:$BD$379,BJ4) -> 598.6 | BK9: =_xlfn.MAXIFS($AY$4:$AY$379,$BD$4:$BD$379,BK4) -> 589.2 | BL9: =_xlfn.MAXIFS($AY$4:$AY$379,$BD$4:$BD$379,BL4) -> 568.9 | BM9: =_xlfn.MAXIFS($AY$4:$AY$379,$BD$4:$BD$379,BM4) -> 583.2 | BN9: =_xlfn.MAXIFS($AY$4:$AY$379,$BD$4:$BD$379,BN4) -> 611.7 | ... BR9: =_xlfn.MAXIFS($AY$4:$AY$379,$BD$4:$BD$379,BR4) -> 502.4 | BS9: =MAX(BG9:BR9) -> 611.7 | BZ9: =BZ8+1 -> 46018 | CA9: =AY375 -> 179.4 | CB9: =IF(CA9=0,1,0) -> 0 | CC9: =IFERROR(VLOOKUP(BZ8,'Geração Equatorial x Medido'!$O$4:$P$55,2,FALSE),"") | CD9: =IF(CC9="",CD8,CC9) -> 45992 | CE9: =IFERROR(VLOOKUP(BZ9,$H$422:$J$469,3,FALSE),"") | CH9: Máxima anual (kWh/mês) | CI9: =_xlfn.MAXIFS($CA$4:$CA$368,$CF$4:$CF$368,CI4) -> 526.9 | CJ9: =_xlfn.MAXIFS($CA$4:$CA$368,$CF$4:$CF$368,CJ4) -> 530 | CK9: =_xlfn.MAXIFS($CA$4:$CA$368,$CF$4:$CF$368,CK4) -> 596 | CL9: =_xlfn.MAXIFS($CA$4:$CA$368,$CF$4:$CF$368,CL4) -> 531.3 | CM9: =_xlfn.MAXIFS($CA$4:$CA$368,$CF$4:$CF$368,CM4) -> 0 | CN9: =_xlfn.MAXIFS($CA$4:$CA$368,$CF$4:$CF$368,CN4) -> 0 | CO9: =_xlfn.MAXIFS($CA$4:$CA$368,$CF$4:$CF$368,CO4) -> 0 | CP9: =_xlfn.MAXIFS($CA$4:$CA$368,$CF$4:$CF$368,CP4) -> 0 | ... CT9: =_xlfn.MAXIFS($CA$4:$CA$368,$CF$4:$CF$368,CT4) -> 0 | CU9: =MAX(CI9:CT9) -> 596
A10: =A9+1 -> 44933 | B10: 0 | C10: =IFERROR(VLOOKUP(A10,'Geração Equatorial x Medido'!$O$4:$P$15,2,FALSE),"") | D10: =IF(C10="",D9,C10) -> 44896 | E10: =IFERROR(VLOOKUP(A10,$H$422:$J$433,3,FALSE),"") | F10: =IF(E10="",F9,E10) -> 44927 | Y10: =Y9+1 -> 45293 | Z10: 336 | AA10: =IF(Z10=0,1,0) -> 0 | AB10: =IFERROR(VLOOKUP(Y10,'Geração Equatorial x Medido'!$O$15:$R$18,2,FALSE),"") | AC10: =IF(AB10="",AC9,AB10) -> 45261 | AD10: =IFERROR(VLOOKUP(Y10,$H$422:$J$457,3,FALSE),"") | AE10: =IF(AD10="",AE9,AD10) -> 45292 | AG10: Máximo mensal no ano | AH10: =IF(AH6=MAX($AH$6:$AS$6),AH6,"") | AI10: =IF(AI6=MAX($AH$6:$AS$6),AI6,"") | AJ10: =IF(AJ6=MAX($AH$6:$AS$6),AJ6,"") | AK10: =IF(AK6=MAX($AH$6:$AS$6),AK6,"") | AL10: =IF(AL6=MAX($AH$6:$AS$6),AL6,"") | AM10: =IF(AM6=MAX($AH$6:$AS$6),AM6,"") | AN10: =IF(AN6=MAX($AH$6:$AS$6),AN6,"") | AO10: =IF(AO6=MAX($AH$6:$AS$6),AO6,"") | ... AS10: =IF(AS6=MAX($AH$6:$AS$6),AS6,"") | AX10: =AX9+1 -> 45653 | AY10: 221.4 | AZ10: =IF(AY10=0,1,0) -> 0 | BA10: =IFERROR(VLOOKUP(AX9,'Geração Equatorial x Medido'!$O$4:$P$55,2,FALSE),"") | BB10: =IF(BA10="",BB9,BA10) -> 45627 | BC10: =IFERROR(VLOOKUP(AX10,$H$422:$J$457,3,FALSE),"") | BF10: Máximo mensal no ano | BG10: =IF(BG6=MAX($BG$6:$BR$6),BG6,"") | BH10: =IF(BH6=MAX($BG$6:$BR$6),BH6,"") | BI10: =IF(BI6=MAX($BG$6:$BR$6),BI6,"") | BJ10: =IF(BJ6=MAX($BG$6:$BR$6),BJ6,"") | BK10: =IF(BK6=MAX($BG$6:$BR$6),BK6,"") | BL10: =IF(BL6=MAX($BG$6:$BR$6),BL6,"") | BM10: =IF(BM6=MAX($BG$6:$BR$6),BM6,"") | BN10: =IF(BN6=MAX($BG$6:$BR$6),BN6,"") -> 16483.5 | ... BR10: =IF(BR6=MAX($BG$6:$BR$6),BR6,"") | BZ10: =BZ9+1 -> 46019 | CA10: =AY376 -> 197.9 | CB10: =IF(CA10=0,1,0) -> 0 | CC10: =IFERROR(VLOOKUP(BZ9,'Geração Equatorial x Medido'!$O$4:$P$55,2,FALSE),"") -> 45992 | CD10: =IF(CC10="",CD9,CC10) -> 45992 | CE10: =IFERROR(VLOOKUP(BZ10,$H$422:$J$469,3,FALSE),"") | CH10: Máximo mensal no ano | CI10: =IF(CI6=MAX($CI$6:$CT$6),CI6,"") | CJ10: =IF(CJ6=MAX($CI$6:$CT$6),CJ6,"") -> 12332.2 | CK10: =IF(CK6=MAX($CI$6:$CT$6),CK6,"") | CL10: =IF(CL6=MAX($CI$6:$CT$6),CL6,"") | CM10: =IF(CM6=MAX($CI$6:$CT$6),CM6,"") | CN10: =IF(CN6=MAX($CI$6:$CT$6),CN6,"") | CO10: =IF(CO6=MAX($CI$6:$CT$6),CO6,"") | CP10: =IF(CP6=MAX($CI$6:$CT$6),CP6,"") | ... CT10: =IF(CT6=MAX($CI$6:$CT$6),CT6,"")
A11: =A10+1 -> 44934 | B11: 0 | C11: =IFERROR(VLOOKUP(A11,'Geração Equatorial x Medido'!$O$4:$P$15,2,FALSE),"") | D11: =IF(C11="",D10,C11) -> 44896 | E11: =IFERROR(VLOOKUP(A11,$H$422:$J$433,3,FALSE),"") | F11: =IF(E11="",F10,E11) -> 44927 | Y11: =Y10+1 -> 45294 | Z11: 352.1 | AA11: =IF(Z11=0,1,0) -> 0 | AB11: =IFERROR(VLOOKUP(Y11,'Geração Equatorial x Medido'!$O$15:$R$18,2,FALSE),"") | AC11: =IF(AB11="",AC10,AB11) -> 45261 | AD11: =IFERROR(VLOOKUP(Y11,$H$422:$J$457,3,FALSE),"") | AE11: =IF(AD11="",AE10,AD11) -> 45292 | AX11: =AX10+1 -> 45654 | AY11: 395.8 | AZ11: =IF(AY11=0,1,0) -> 0 | BA11: =IFERROR(VLOOKUP(AX10,'Geração Equatorial x Medido'!$O$4:$P$55,2,FALSE),"") -> 45627 | BB11: =IF(BA11="",BB12,BA11) -> 45627 | BC11: =IFERROR(VLOOKUP(AX11,$H$422:$J$457,3,FALSE),"") | BF11: Dias sem Geração | BG11: =SUMIF($BB:$BB,BG4,$AZ:$AZ) -> 0 | BH11: =SUMIF($BB:$BB,BH4,$AZ:$AZ) -> 0 | BI11: =SUMIF($BB:$BB,BI4,$AZ:$AZ) -> 0 | BJ11: =SUMIF($BB:$BB,BJ4,$AZ:$AZ) -> 0 | BK11: =SUMIF($BB:$BB,BK4,$AZ:$AZ) -> 0 | BL11: =SUMIF($BB:$BB,BL4,$AZ:$AZ) -> 0 | BM11: =SUMIF($BB:$BB,BM4,$AZ:$AZ) -> 0 | BN11: =SUMIF($BB:$BB,BN4,$AZ:$AZ) -> 0 | ... BR11: =SUMIF($BB:$BB,BR4,$AZ:$AZ) -> 0 | BZ11: =BZ10+1 -> 46020 | CA11: =AY377 -> 204.5 | CB11: =IF(CA11=0,1,0) -> 0 | CC11: =IFERROR(VLOOKUP(BZ10,'Geração Equatorial x Medido'!$O$4:$P$55,2,FALSE),"") | CD11: =IF(CC11="",CD12,CC11) -> 46023 | CE11: =IFERROR(VLOOKUP(BZ11,$H$422:$J$469,3,FALSE),"") | CH11: Dias sem Geração | CI11: =SUMIF($CD$10:$CD$378,CI4,$CB$10:$CB$378) -> 0 | CJ11: =SUMIF($CD$10:$CD$378,CJ4,$CB$10:$CB$378) -> 0 | CK11: =SUMIF($CD$10:$CD$378,CK4,$CB$10:$CB$378) -> 0 | CL11: =SUMIF($CD$10:$CD$378,CL4,$CB$10:$CB$378) -> 23 | CM11: =SUMIF($CD$10:$CD$378,CM4,$CB$10:$CB$378) -> 30 | CN11: =SUMIF($CD$10:$CD$378,CN4,$CB$10:$CB$378) -> 31 | CO11: =SUMIF($CD$10:$CD$378,CO4,$CB$10:$CB$378) -> 30 | CP11: =SUMIF($CD$10:$CD$378,CP4,$CB$10:$CB$378) -> 31 | ... CT11: =SUMIF($CD$10:$CD$378,CT4,$CB$10:$CB$378) -> 30
A12: =A11+1 -> 44935 | B12: 0 | C12: =IFERROR(VLOOKUP(A12,'Geração Equatorial x Medido'!$O$4:$P$15,2,FALSE),"") | D12: =IF(C12="",D11,C12) -> 44896 | E12: =IFERROR(VLOOKUP(A12,$H$422:$J$433,3,FALSE),"") | F12: =IF(E12="",F11,E12) -> 44927 | Y12: =Y11+1 -> 45295 | Z12: 489.5 | AA12: =IF(Z12=0,1,0) -> 0 | AB12: =IFERROR(VLOOKUP(Y12,'Geração Equatorial x Medido'!$O$15:$R$18,2,FALSE),"") | AC12: =IF(AB12="",AC11,AB12) -> 45261 | AD12: =IFERROR(VLOOKUP(Y12,$H$422:$J$457,3,FALSE),"") | AE12: =IF(AD12="",AE11,AD12) -> 45292 | AX12: =AX11+1 -> 45655 | AY12: 483.7 | AZ12: =IF(AY12=0,1,0) -> 0 | BA12: =IFERROR(VLOOKUP(AX11,'Geração Equatorial x Medido'!$O$4:$P$55,2,FALSE),"") | BB12: =IF(BA12="",BB13,BA12) -> 45658 | BC12: =IFERROR(VLOOKUP(AX12,$H$422:$J$457,3,FALSE),"") | BZ12: =BZ11+1 -> 46021 | CA12: =AY378 -> 187.8 | CB12: =IF(CA12=0,1,0) -> 0 | CC12: =IFERROR(VLOOKUP(BZ11,'Geração Equatorial x Medido'!$O$4:$P$55,2,FALSE),"") | CD12: =IF(CC12="",CD13,CC12) -> 46023 | CE12: =IFERROR(VLOOKUP(BZ12,$H$422:$J$469,3,FALSE),"")
A13: =A12+1 -> 44936 | B13: 0 | C13: =IFERROR(VLOOKUP(A13,'Geração Equatorial x Medido'!$O$4:$P$15,2,FALSE),"") | D13: =IF(C13="",D12,C13) -> 44896 | E13: =IFERROR(VLOOKUP(A13,$H$422:$J$433,3,FALSE),"") | F13: =IF(E13="",F12,E13) -> 44927 | Y13: =Y12+1 -> 45296 | Z13: 529.5 | AA13: =IF(Z13=0,1,0) -> 0 | AB13: =IFERROR(VLOOKUP(Y13,'Geração Equatorial x Medido'!$O$15:$R$18,2,FALSE),"") | AC13: =IF(AB13="",AC12,AB13) -> 45261 | AD13: =IFERROR(VLOOKUP(Y13,$H$422:$J$457,3,FALSE),"") | AE13: =IF(AD13="",AE12,AD13) -> 45292 | AX13: =AX12+1 -> 45656 | AY13: 482.2 | AZ13: =IF(AY13=0,1,0) -> 0 | BA13: =IFERROR(VLOOKUP(AX12,'Geração Equatorial x Medido'!$O$4:$P$55,2,FALSE),"") | BB13: =IF(BA13="",BB14,BA13) -> 45658 | BC13: =IFERROR(VLOOKUP(AX13,$H$422:$J$457,3,FALSE),"") | BZ13: =BZ12+1 -> 46022 | CA13: =AY379 -> 179.7 | CB13: =IF(CA13=0,1,0) -> 0 | CC13: =IFERROR(VLOOKUP(BZ12,'Geração Equatorial x Medido'!$O$4:$P$55,2,FALSE),"") | CD13: =IF(CC13="",CD14,CC13) -> 46023 | CE13: =IFERROR(VLOOKUP(BZ13,$H$422:$J$469,3,FALSE),"")
A14: =A13+1 -> 44937 | B14: 0 | C14: =IFERROR(VLOOKUP(A14,'Geração Equatorial x Medido'!$O$4:$P$15,2,FALSE),"") | D14: =IF(C14="",D13,C14) -> 44896 | E14: =IFERROR(VLOOKUP(A14,$H$422:$J$433,3,FALSE),"") | F14: =IF(E14="",F13,E14) -> 44927 | Y14: =Y13+1 -> 45297 | Z14: 442 | AA14: =IF(Z14=0,1,0) -> 0 | AB14: =IFERROR(VLOOKUP(Y14,'Geração Equatorial x Medido'!$O$15:$R$18,2,FALSE),"") | AC14: =IF(AB14="",AC13,AB14) -> 45261 | AD14: =IFERROR(VLOOKUP(Y14,$H$422:$J$457,3,FALSE),"") | AE14: =IF(AD14="",AE13,AD14) -> 45292 | AX14: =AX13+1 -> 45657 | AY14: 477.9 | AZ14: =IF(AY14=0,1,0) -> 0 | BA14: =IFERROR(VLOOKUP(AX13,'Geração Equatorial x Medido'!$O$4:$P$55,2,FALSE),"") | BB14: =IF(BA14="",BB15,BA14) -> 45658 | BC14: =IFERROR(VLOOKUP(AX14,$H$422:$J$457,3,FALSE),"") | BZ14: =BZ13+1 -> 46023 | CA14: 182.1 | CB14: =IF(CA14=0,1,0) -> 0 | CC14: =IFERROR(VLOOKUP(BZ13,'Geração Equatorial x Medido'!$O$4:$P$55,2,FALSE),"") | CD14: =IF(CC14="",CD15,CC14) -> 46023 | CE14: =IFERROR(VLOOKUP(BZ14,$H$422:$J$469,3,FALSE),"") -> 46023 | CF14: =IF(CE14="",CF13,CE14) -> 46023
A15: =A14+1 -> 44938 | B15: 0 | C15: =IFERROR(VLOOKUP(A15,'Geração Equatorial x Medido'!$O$4:$P$15,2,FALSE),"") | D15: =IF(C15="",D14,C15) -> 44896 | E15: =IFERROR(VLOOKUP(A15,$H$422:$J$433,3,FALSE),"") | F15: =IF(E15="",F14,E15) -> 44927 | Y15: =Y14+1 -> 45298 | Z15: 216.7 | AA15: =IF(Z15=0,1,0) -> 0 | AB15: =IFERROR(VLOOKUP(Y15,'Geração Equatorial x Medido'!$O$15:$R$18,2,FALSE),"") | AC15: =IF(AB15="",AC14,AB15) -> 45261 | AD15: =IFERROR(VLOOKUP(Y15,$H$422:$J$457,3,FALSE),"") | AE15: =IF(AD15="",AE14,AD15) -> 45292 | AX15: =AX14+1 -> 45658 | AY15: 459.1 | AZ15: =IF(AY15=0,1,0) -> 0 | BA15: =IFERROR(VLOOKUP(AX14,'Geração Equatorial x Medido'!$O$4:$P$55,2,FALSE),"") | BB15: =IF(BA15="",BB16,BA15) -> 45658 | BC15: =IFERROR(VLOOKUP(AX15,$H$422:$J$457,3,FALSE),"") -> 45658 | BD15: =IF(BC15="",BD14,BC15) -> 45658 | BZ15: =BZ14+1 -> 46024 | CA15: 183.3 | CB15: =IF(CA15=0,1,0) -> 0 | CC15: =IFERROR(VLOOKUP(BZ14,'Geração Equatorial x Medido'!$O$4:$P$55,2,FALSE),"") | CD15: =IF(CC15="",CD16,CC15) -> 46023 | CE15: =IFERROR(VLOOKUP(BZ15,$H$422:$J$469,3,FALSE),"") | CF15: =IF(CE15="",CF14,CE15) -> 46023 | CY15: 14000
A16: =A15+1 -> 44939 | B16: 0 | C16: =IFERROR(VLOOKUP(A16,'Geração Equatorial x Medido'!$O$4:$P$15,2,FALSE),"") | D16: =IF(C16="",D15,C16) -> 44896 | E16: =IFERROR(VLOOKUP(A16,$H$422:$J$433,3,FALSE),"") | F16: =IF(E16="",F15,E16) -> 44927 | Y16: =Y15+1 -> 45299 | Z16: 435.5 | AA16: =IF(Z16=0,1,0) -> 0 | AB16: =IFERROR(VLOOKUP(Y16,'Geração Equatorial x Medido'!$O$15:$R$18,2,FALSE),"") | AC16: =IF(AB16="",AC15,AB16) -> 45261 | AD16: =IFERROR(VLOOKUP(Y16,$H$422:$J$457,3,FALSE),"") | AE16: =IF(AD16="",AE15,AD16) -> 45292 | AX16: =AX15+1 -> 45659 | AY16: 467.2 | AZ16: =IF(AY16=0,1,0) -> 0 | BA16: =IFERROR(VLOOKUP(AX15,'Geração Equatorial x Medido'!$O$4:$P$55,2,FALSE),"") | BB16: =IF(BA16="",BB17,BA16) -> 45658 | BC16: =IFERROR(VLOOKUP(AX16,$H$422:$J$457,3,FALSE),"") | BD16: =IF(BC16="",BD15,BC16) -> 45658 | BZ16: =BZ15+1 -> 46025 | CA16: 199.3 | CB16: =IF(CA16=0,1,0) -> 0 | CC16: =IFERROR(VLOOKUP(BZ15,'Geração Equatorial x Medido'!$O$4:$P$55,2,FALSE),"") | CD16: =IF(CC16="",CD17,CC16) -> 46023 | CE16: =IFERROR(VLOOKUP(BZ16,$H$422:$J$469,3,FALSE),"") | CF16: =IF(CE16="",CF15,CE16) -> 46023 | CY16: 31
A17: =A16+1 -> 44940 | B17: 0 | C17: =IFERROR(VLOOKUP(A17,'Geração Equatorial x Medido'!$O$4:$P$15,2,FALSE),"") | D17: =IF(C17="",D16,C17) -> 44896 | E17: =IFERROR(VLOOKUP(A17,$H$422:$J$433,3,FALSE),"") | F17: =IF(E17="",F16,E17) -> 44927 | Y17: =Y16+1 -> 45300 | Z17: 359 | AA17: =IF(Z17=0,1,0) -> 0 | AB17: =IFERROR(VLOOKUP(Y17,'Geração Equatorial x Medido'!$O$15:$R$18,2,FALSE),"") | AC17: =IF(AB17="",AC16,AB17) -> 45261 | AD17: =IFERROR(VLOOKUP(Y17,$H$422:$J$457,3,FALSE),"") | AE17: =IF(AD17="",AE16,AD17) -> 45292 | AX17: =AX16+1 -> 45660 | AY17: 459 | AZ17: =IF(AY17=0,1,0) -> 0 | BA17: =IFERROR(VLOOKUP(AX16,'Geração Equatorial x Medido'!$O$4:$P$55,2,FALSE),"") | BB17: =IF(BA17="",BB18,BA17) -> 45658 | BC17: =IFERROR(VLOOKUP(AX17,$H$422:$J$457,3,FALSE),"") | BD17: =IF(BC17="",BD16,BC17) -> 45658 | BZ17: =BZ16+1 -> 46026 | CA17: 198.3 | CB17: =IF(CA17=0,1,0) -> 0 | CC17: =IFERROR(VLOOKUP(BZ16,'Geração Equatorial x Medido'!$O$4:$P$55,2,FALSE),"") | CD17: =IF(CC17="",CD18,CC17) -> 46023 | CE17: =IFERROR(VLOOKUP(BZ17,$H$422:$J$469,3,FALSE),"") | CF17: =IF(CE17="",CF16,CE17) -> 46023 | CY17: =CY15/CY16 -> 451.6129
A18: =A17+1 -> 44941 | B18: 0 | C18: =IFERROR(VLOOKUP(A18,'Geração Equatorial x Medido'!$O$4:$P$15,2,FALSE),"") | D18: =IF(C18="",D17,C18) -> 44896 | E18: =IFERROR(VLOOKUP(A18,$H$422:$J$433,3,FALSE),"") | F18: =IF(E18="",F17,E18) -> 44927 | Y18: =Y17+1 -> 45301 | Z18: 448.8 | AA18: =IF(Z18=0,1,0) -> 0 | AB18: =IFERROR(VLOOKUP(Y18,'Geração Equatorial x Medido'!$O$15:$R$18,2,FALSE),"") | AC18: =IF(AB18="",AC17,AB18) -> 45261 | AD18: =IFERROR(VLOOKUP(Y18,$H$422:$J$457,3,FALSE),"") | AE18: =IF(AD18="",AE17,AD18) -> 45292 | AX18: =AX17+1 -> 45661 | AY18: 344.2 | AZ18: =IF(AY18=0,1,0) -> 0 | BA18: =IFERROR(VLOOKUP(AX17,'Geração Equatorial x Medido'!$O$4:$P$55,2,FALSE),"") | BB18: =IF(BA18="",BB19,BA18) -> 45658 | BC18: =IFERROR(VLOOKUP(AX18,$H$422:$J$457,3,FALSE),"") | BD18: =IF(BC18="",BD17,BC18) -> 45658 | BZ18: =BZ17+1 -> 46027 | CA18: 200.8 | CB18: =IF(CA18=0,1,0) -> 0 | CC18: =IFERROR(VLOOKUP(BZ17,'Geração Equatorial x Medido'!$O$4:$P$55,2,FALSE),"") | CD18: =IF(CC18="",CD19,CC18) -> 46023 | CE18: =IFERROR(VLOOKUP(BZ18,$H$422:$J$469,3,FALSE),"") | CF18: =IF(CE18="",CF17,CE18) -> 46023 | CY18: 451.6129
A19: =A18+1 -> 44942 | B19: 0 | C19: =IFERROR(VLOOKUP(A19,'Geração Equatorial x Medido'!$O$4:$P$15,2,FALSE),"") | D19: =IF(C19="",D18,C19) -> 44896 | E19: =IFERROR(VLOOKUP(A19,$H$422:$J$433,3,FALSE),"") | F19: =IF(E19="",F18,E19) -> 44927 | Y19: =Y18+1 -> 45302 | Z19: 440.1 | AA19: =IF(Z19=0,1,0) -> 0 | AB19: =IFERROR(VLOOKUP(Y19,'Geração Equatorial x Medido'!$O$15:$R$18,2,FALSE),"") | AC19: =IF(AB19="",AC18,AB19) -> 45261 | AD19: =IFERROR(VLOOKUP(Y19,$H$422:$J$457,3,FALSE),"") | AE19: =IF(AD19="",AE18,AD19) -> 45292 | AX19: =AX18+1 -> 45662 | AY19: 461 | AZ19: =IF(AY19=0,1,0) -> 0 | BA19: =IFERROR(VLOOKUP(AX18,'Geração Equatorial x Medido'!$O$4:$P$55,2,FALSE),"") | BB19: =IF(BA19="",BB20,BA19) -> 45658 | BC19: =IFERROR(VLOOKUP(AX19,$H$422:$J$457,3,FALSE),"") | BD19: =IF(BC19="",BD18,BC19) -> 45658 | BZ19: =BZ18+1 -> 46028 | CA19: 428.3 | CB19: =IF(CA19=0,1,0) -> 0 | CC19: =IFERROR(VLOOKUP(BZ18,'Geração Equatorial x Medido'!$O$4:$P$55,2,FALSE),"") | CD19: =IF(CC19="",CD20,CC19) -> 46023 | CE19: =IFERROR(VLOOKUP(BZ19,$H$422:$J$469,3,FALSE),"") | CF19: =IF(CE19="",CF18,CE19) -> 46023
A20: =A19+1 -> 44943 | B20: 0 | C20: =IFERROR(VLOOKUP(A20,'Geração Equatorial x Medido'!$O$4:$P$15,2,FALSE),"") | D20: =IF(C20="",D19,C20) -> 44896 | E20: =IFERROR(VLOOKUP(A20,$H$422:$J$433,3,FALSE),"") | F20: =IF(E20="",F19,E20) -> 44927 | Y20: =Y19+1 -> 45303 | Z20: 109.6 | AA20: =IF(Z20=0,1,0) -> 0 | AB20: =IFERROR(VLOOKUP(Y20,'Geração Equatorial x Medido'!$O$15:$R$18,2,FALSE),"") | AC20: =IF(AB20="",AC19,AB20) -> 45261 | AD20: =IFERROR(VLOOKUP(Y20,$H$422:$J$457,3,FALSE),"") | AE20: =IF(AD20="",AE19,AD20) -> 45292 | AX20: =AX19+1 -> 45663 | AY20: 460.4 | AZ20: =IF(AY20=0,1,0) -> 0 | BA20: =IFERROR(VLOOKUP(AX19,'Geração Equatorial x Medido'!$O$4:$P$55,2,FALSE),"") | BB20: =IF(BA20="",BB21,BA20) -> 45658 | BC20: =IFERROR(VLOOKUP(AX20,$H$422:$J$457,3,FALSE),"") | BD20: =IF(BC20="",BD19,BC20) -> 45658 | BZ20: =BZ19+1 -> 46029 | CA20: 439 | CB20: =IF(CA20=0,1,0) -> 0 | CC20: =IFERROR(VLOOKUP(BZ19,'Geração Equatorial x Medido'!$O$4:$P$55,2,FALSE),"") | CD20: =IF(CC20="",CD21,CC20) -> 46023 | CE20: =IFERROR(VLOOKUP(BZ20,$H$422:$J$469,3,FALSE),"") | CF20: =IF(CE20="",CF19,CE20) -> 46023
A21: =A20+1 -> 44944 | B21: 0 | C21: =IFERROR(VLOOKUP(A21,'Geração Equatorial x Medido'!$O$4:$P$15,2,FALSE),"") | D21: =IF(C21="",D20,C21) -> 44896 | E21: =IFERROR(VLOOKUP(A21,$H$422:$J$433,3,FALSE),"") | F21: =IF(E21="",F20,E21) -> 44927 | Y21: =Y20+1 -> 45304 | Z21: 193.7 | AA21: =IF(Z21=0,1,0) -> 0 | AB21: =IFERROR(VLOOKUP(Y21,'Geração Equatorial x Medido'!$O$15:$R$18,2,FALSE),"") | AC21: =IF(AB21="",AC20,AB21) -> 45261 | AD21: =IFERROR(VLOOKUP(Y21,$H$422:$J$457,3,FALSE),"") | AE21: =IF(AD21="",AE20,AD21) -> 45292 | AX21: =AX20+1 -> 45664 | AY21: 318.8 | AZ21: =IF(AY21=0,1,0) -> 0 | BA21: =IFERROR(VLOOKUP(AX20,'Geração Equatorial x Medido'!$O$4:$P$55,2,FALSE),"") | BB21: =IF(BA21="",BB22,BA21) -> 45658 | BC21: =IFERROR(VLOOKUP(AX21,$H$422:$J$457,3,FALSE),"") | BD21: =IF(BC21="",BD20,BC21) -> 45658 | BZ21: =BZ20+1 -> 46030 | CA21: 491.6 | CB21: =IF(CA21=0,1,0) -> 0 | CC21: =IFERROR(VLOOKUP(BZ20,'Geração Equatorial x Medido'!$O$4:$P$55,2,FALSE),"") | CD21: =IF(CC21="",CD22,CC21) -> 46023 | CE21: =IFERROR(VLOOKUP(BZ21,$H$422:$J$469,3,FALSE),"") | CF21: =IF(CE21="",CF20,CE21) -> 46023
A22: =A21+1 -> 44945 | B22: 0 | C22: =IFERROR(VLOOKUP(A22,'Geração Equatorial x Medido'!$O$4:$P$15,2,FALSE),"") | D22: =IF(C22="",D21,C22) -> 44896 | E22: =IFERROR(VLOOKUP(A22,$H$422:$J$433,3,FALSE),"") | F22: =IF(E22="",F21,E22) -> 44927 | Y22: =Y21+1 -> 45305 | Z22: 418.2 | AA22: =IF(Z22=0,1,0) -> 0 | AB22: =IFERROR(VLOOKUP(Y22,'Geração Equatorial x Medido'!$O$15:$R$18,2,FALSE),"") | AC22: =IF(AB22="",AC21,AB22) -> 45261 | AD22: =IFERROR(VLOOKUP(Y22,$H$422:$J$457,3,FALSE),"") | AE22: =IF(AD22="",AE21,AD22) -> 45292 | AX22: =AX21+1 -> 45665 | AY22: 352.4 | AZ22: =IF(AY22=0,1,0) -> 0 | BA22: =IFERROR(VLOOKUP(AX21,'Geração Equatorial x Medido'!$O$4:$P$55,2,FALSE),"") | BB22: =IF(BA22="",BB23,BA22) -> 45658 | BC22: =IFERROR(VLOOKUP(AX22,$H$422:$J$457,3,FALSE),"") | BD22: =IF(BC22="",BD21,BC22) -> 45658 | BZ22: =BZ21+1 -> 46031 | CA22: 495.1 | CB22: =IF(CA22=0,1,0) -> 0 | CC22: =IFERROR(VLOOKUP(BZ21,'Geração Equatorial x Medido'!$O$4:$P$55,2,FALSE),"") | CD22: =IF(CC22="",CD23,CC22) -> 46023 | CE22: =IFERROR(VLOOKUP(BZ22,$H$422:$J$469,3,FALSE),"") | CF22: =IF(CE22="",CF21,CE22) -> 46023
A23: =A22+1 -> 44946 | B23: 0 | C23: =IFERROR(VLOOKUP(A23,'Geração Equatorial x Medido'!$O$4:$P$15,2,FALSE),"") | D23: =IF(C23="",D22,C23) -> 44896 | E23: =IFERROR(VLOOKUP(A23,$H$422:$J$433,3,FALSE),"") | F23: =IF(E23="",F22,E23) -> 44927 | Y23: =Y22+1 -> 45306 | Z23: 394.6 | AA23: =IF(Z23=0,1,0) -> 0 | AB23: =IFERROR(VLOOKUP(Y23,'Geração Equatorial x Medido'!$O$15:$R$18,2,FALSE),"") | AC23: =IF(AB23="",AC22,AB23) -> 45261 | AD23: =IFERROR(VLOOKUP(Y23,$H$422:$J$457,3,FALSE),"") | AE23: =IF(AD23="",AE22,AD23) -> 45292 | AX23: =AX22+1 -> 45666 | AY23: 329.6 | AZ23: =IF(AY23=0,1,0) -> 0 | BA23: =IFERROR(VLOOKUP(AX22,'Geração Equatorial x Medido'!$O$4:$P$55,2,FALSE),"") | BB23: =IF(BA23="",BB24,BA23) -> 45658 | BC23: =IFERROR(VLOOKUP(AX23,$H$422:$J$457,3,FALSE),"") | BD23: =IF(BC23="",BD22,BC23) -> 45658 | BZ23: =BZ22+1 -> 46032 | CA23: 495.9 | CB23: =IF(CA23=0,1,0) -> 0 | CC23: =IFERROR(VLOOKUP(BZ22,'Geração Equatorial x Medido'!$O$4:$P$55,2,FALSE),"") | CD23: =IF(CC23="",CD24,CC23) -> 46023 | CE23: =IFERROR(VLOOKUP(BZ23,$H$422:$J$469,3,FALSE),"") | CF23: =IF(CE23="",CF22,CE23) -> 46023
A24: =A23+1 -> 44947 | B24: 0 | C24: =IFERROR(VLOOKUP(A24,'Geração Equatorial x Medido'!$O$4:$P$15,2,FALSE),"") | D24: =IF(C24="",D23,C24) -> 44896 | E24: =IFERROR(VLOOKUP(A24,$H$422:$J$433,3,FALSE),"") | F24: =IF(E24="",F23,E24) -> 44927 | Y24: =Y23+1 -> 45307 | Z24: 431.8 | AA24: =IF(Z24=0,1,0) -> 0 | AB24: =IFERROR(VLOOKUP(Y24,'Geração Equatorial x Medido'!$O$15:$R$18,2,FALSE),"") | AC24: =IF(AB24="",AC23,AB24) -> 45261 | AD24: =IFERROR(VLOOKUP(Y24,$H$422:$J$457,3,FALSE),"") | AE24: =IF(AD24="",AE23,AD24) -> 45292 | AX24: =AX23+1 -> 45667 | AY24: 419.8 | AZ24: =IF(AY24=0,1,0) -> 0 | BA24: =IFERROR(VLOOKUP(AX23,'Geração Equatorial x Medido'!$O$4:$P$55,2,FALSE),"") | BB24: =IF(BA24="",BB25,BA24) -> 45658 | BC24: =IFERROR(VLOOKUP(AX24,$H$422:$J$457,3,FALSE),"") | BD24: =IF(BC24="",BD23,BC24) -> 45658 | BZ24: =BZ23+1 -> 46033 | CA24: 460.6 | CB24: =IF(CA24=0,1,0) -> 0 | CC24: =IFERROR(VLOOKUP(BZ23,'Geração Equatorial x Medido'!$O$4:$P$55,2,FALSE),"") | CD24: =IF(CC24="",CD25,CC24) -> 46023 | CE24: =IFERROR(VLOOKUP(BZ24,$H$422:$J$469,3,FALSE),"") | CF24: =IF(CE24="",CF23,CE24) -> 46023
A25: =A24+1 -> 44948 | B25: 0 | C25: =IFERROR(VLOOKUP(A25,'Geração Equatorial x Medido'!$O$4:$P$15,2,FALSE),"") | D25: =IF(C25="",D24,C25) -> 44896 | E25: =IFERROR(VLOOKUP(A25,$H$422:$J$433,3,FALSE),"") | F25: =IF(E25="",F24,E25) -> 44927 | Y25: =Y24+1 -> 45308 | Z25: 502.3 | AA25: =IF(Z25=0,1,0) -> 0 | AB25: =IFERROR(VLOOKUP(Y25,'Geração Equatorial x Medido'!$O$15:$R$18,2,FALSE),"") | AC25: =IF(AB25="",AC24,AB25) -> 45261 | AD25: =IFERROR(VLOOKUP(Y25,$H$422:$J$457,3,FALSE),"") | AE25: =IF(AD25="",AE24,AD25) -> 45292 | AX25: =AX24+1 -> 45668 | AY25: 442.2 | AZ25: =IF(AY25=0,1,0) -> 0 | BA25: =IFERROR(VLOOKUP(AX24,'Geração Equatorial x Medido'!$O$4:$P$55,2,FALSE),"") | BB25: =IF(BA25="",BB26,BA25) -> 45658 | BC25: =IFERROR(VLOOKUP(AX25,$H$422:$J$457,3,FALSE),"") | BD25: =IF(BC25="",BD24,BC25) -> 45658 | BZ25: =BZ24+1 -> 46034 | CA25: 496.7 | CB25: =IF(CA25=0,1,0) -> 0 | CC25: =IFERROR(VLOOKUP(BZ24,'Geração Equatorial x Medido'!$O$4:$P$55,2,FALSE),"") | CD25: =IF(CC25="",CD26,CC25) -> 46023 | CE25: =IFERROR(VLOOKUP(BZ25,$H$422:$J$469,3,FALSE),"") | CF25: =IF(CE25="",CF24,CE25) -> 46023
A26: =A25+1 -> 44949 | B26: 0 | C26: =IFERROR(VLOOKUP(A26,'Geração Equatorial x Medido'!$O$4:$P$15,2,FALSE),"") | D26: =IF(C26="",D25,C26) -> 44896 | E26: =IFERROR(VLOOKUP(A26,$H$422:$J$433,3,FALSE),"") | F26: =IF(E26="",F25,E26) -> 44927 | Y26: =Y25+1 -> 45309 | Z26: 517.2 | AA26: =IF(Z26=0,1,0) -> 0 | AB26: =IFERROR(VLOOKUP(Y26,'Geração Equatorial x Medido'!$O$15:$R$18,2,FALSE),"") | AC26: =IF(AB26="",AC25,AB26) -> 45261 | AD26: =IFERROR(VLOOKUP(Y26,$H$422:$J$457,3,FALSE),"") | AE26: =IF(AD26="",AE25,AD26) -> 45292 | AX26: =AX25+1 -> 45669 | AY26: 369.6 | AZ26: =IF(AY26=0,1,0) -> 0 | BA26: =IFERROR(VLOOKUP(AX25,'Geração Equatorial x Medido'!$O$4:$P$55,2,FALSE),"") | BB26: =IF(BA26="",BB27,BA26) -> 45658 | BC26: =IFERROR(VLOOKUP(AX26,$H$422:$J$457,3,FALSE),"") | BD26: =IF(BC26="",BD25,BC26) -> 45658 | BZ26: =BZ25+1 -> 46035 | CA26: 466.6 | CB26: =IF(CA26=0,1,0) -> 0 | CC26: =IFERROR(VLOOKUP(BZ25,'Geração Equatorial x Medido'!$O$4:$P$55,2,FALSE),"") | CD26: =IF(CC26="",CD27,CC26) -> 46023 | CE26: =IFERROR(VLOOKUP(BZ26,$H$422:$J$469,3,FALSE),"") | CF26: =IF(CE26="",CF25,CE26) -> 46023
A27: =A26+1 -> 44950 | B27: 0 | C27: =IFERROR(VLOOKUP(A27,'Geração Equatorial x Medido'!$O$4:$P$15,2,FALSE),"") | D27: =IF(C27="",D26,C27) -> 44896 | E27: =IFERROR(VLOOKUP(A27,$H$422:$J$433,3,FALSE),"") | F27: =IF(E27="",F26,E27) -> 44927 | Y27: =Y26+1 -> 45310 | Z27: 504.4 | AA27: =IF(Z27=0,1,0) -> 0 | AB27: =IFERROR(VLOOKUP(Y27,'Geração Equatorial x Medido'!$O$15:$R$18,2,FALSE),"") | AC27: =IF(AB27="",AC26,AB27) -> 45261 | AD27: =IFERROR(VLOOKUP(Y27,$H$422:$J$457,3,FALSE),"") | AE27: =IF(AD27="",AE26,AD27) -> 45292 | AX27: =AX26+1 -> 45670 | AY27: 355.6 | AZ27: =IF(AY27=0,1,0) -> 0 | BA27: =IFERROR(VLOOKUP(AX26,'Geração Equatorial x Medido'!$O$4:$P$55,2,FALSE),"") | BB27: =IF(BA27="",BB28,BA27) -> 45658 | BC27: =IFERROR(VLOOKUP(AX27,$H$422:$J$457,3,FALSE),"") | BD27: =IF(BC27="",BD26,BC27) -> 45658 | BZ27: =BZ26+1 -> 46036 | CA27: 472.7 | CB27: =IF(CA27=0,1,0) -> 0 | CC27: =IFERROR(VLOOKUP(BZ26,'Geração Equatorial x Medido'!$O$4:$P$55,2,FALSE),"") | CD27: =IF(CC27="",CD28,CC27) -> 46023 | CE27: =IFERROR(VLOOKUP(BZ27,$H$422:$J$469,3,FALSE),"") | CF27: =IF(CE27="",CF26,CE27) -> 46023
A28: =A27+1 -> 44951 | B28: 0 | C28: =IFERROR(VLOOKUP(A28,'Geração Equatorial x Medido'!$O$4:$P$15,2,FALSE),"") | D28: =IF(C28="",D27,C28) -> 44896 | E28: =IFERROR(VLOOKUP(A28,$H$422:$J$433,3,FALSE),"") | F28: =IF(E28="",F27,E28) -> 44927 | Y28: =Y27+1 -> 45311 | Z28: 403.4 | AA28: =IF(Z28=0,1,0) -> 0 | AB28: =IFERROR(VLOOKUP(Y28,'Geração Equatorial x Medido'!$O$15:$R$18,2,FALSE),"") | AC28: =IF(AB28="",AC27,AB28) -> 45261 | AD28: =IFERROR(VLOOKUP(Y28,$H$422:$J$457,3,FALSE),"") | AE28: =IF(AD28="",AE27,AD28) -> 45292 | AX28: =AX27+1 -> 45671 | AY28: 73.3 | AZ28: =IF(AY28=0,1,0) -> 0 | BA28: =IFERROR(VLOOKUP(AX27,'Geração Equatorial x Medido'!$O$4:$P$55,2,FALSE),"") | BB28: =IF(BA28="",BB29,BA28) -> 45658 | BC28: =IFERROR(VLOOKUP(AX28,$H$422:$J$457,3,FALSE),"") | BD28: =IF(BC28="",BD27,BC28) -> 45658 | BZ28: =BZ27+1 -> 46037 | CA28: 429.6 | CB28: =IF(CA28=0,1,0) -> 0 | CC28: =IFERROR(VLOOKUP(BZ27,'Geração Equatorial x Medido'!$O$4:$P$55,2,FALSE),"") | CD28: =IF(CC28="",CD29,CC28) -> 46023 | CE28: =IFERROR(VLOOKUP(BZ28,$H$422:$J$469,3,FALSE),"") | CF28: =IF(CE28="",CF27,CE28) -> 46023
A29: =A28+1 -> 44952 | B29: 0 | C29: =IFERROR(VLOOKUP(A29,'Geração Equatorial x Medido'!$O$4:$P$15,2,FALSE),"") -> 44927 | D29: =IF(C29="",D28,C29) -> 44927 | E29: =IFERROR(VLOOKUP(A29,$H$422:$J$433,3,FALSE),"") | F29: =IF(E29="",F28,E29) -> 44927 | Y29: =Y28+1 -> 45312 | Z29: 481.4 | AA29: =IF(Z29=0,1,0) -> 0 | AB29: =IFERROR(VLOOKUP(Y29,'Geração Equatorial x Medido'!$O$15:$R$18,2,FALSE),"") | AC29: =IF(AB29="",AC28,AB29) -> 45261 | AD29: =IFERROR(VLOOKUP(Y29,$H$422:$J$457,3,FALSE),"") | AE29: =IF(AD29="",AE28,AD29) -> 45292 | AX29: =AX28+1 -> 45672 | AY29: 176.7 | AZ29: =IF(AY29=0,1,0) -> 0 | BA29: =IFERROR(VLOOKUP(AX28,'Geração Equatorial x Medido'!$O$4:$P$55,2,FALSE),"") | BB29: =IF(BA29="",BB30,BA29) -> 45658 | BC29: =IFERROR(VLOOKUP(AX29,$H$422:$J$457,3,FALSE),"") | BD29: =IF(BC29="",BD28,BC29) -> 45658 | BZ29: =BZ28+1 -> 46038 | CA29: 465.8 | CB29: =IF(CA29=0,1,0) -> 0 | CC29: =IFERROR(VLOOKUP(BZ28,'Geração Equatorial x Medido'!$O$4:$P$55,2,FALSE),"") | CD29: =IF(CC29="",CD30,CC29) -> 46023 | CE29: =IFERROR(VLOOKUP(BZ29,$H$422:$J$469,3,FALSE),"") | CF29: =IF(CE29="",CF28,CE29) -> 46023
A30: =A29+1 -> 44953 | B30: 0 | C30: =IFERROR(VLOOKUP(A30,'Geração Equatorial x Medido'!$O$4:$P$15,2,FALSE),"") | D30: =IF(C30="",D29,C30) -> 44927 | E30: =IFERROR(VLOOKUP(A30,$H$422:$J$433,3,FALSE),"") | F30: =IF(E30="",F29,E30) -> 44927 | Y30: =Y29+1 -> 45313 | Z30: 243.7 | AA30: =IF(Z30=0,1,0) -> 0 | AB30: =IFERROR(VLOOKUP(Y30,'Geração Equatorial x Medido'!$O$15:$R$18,2,FALSE),"") | AC30: =IF(AB30="",AC29,AB30) -> 45261 | AD30: =IFERROR(VLOOKUP(Y30,$H$422:$J$457,3,FALSE),"") | AE30: =IF(AD30="",AE29,AD30) -> 45292 | AX30: =AX29+1 -> 45673 | AY30: 231.2 | AZ30: =IF(AY30=0,1,0) -> 0 | BA30: =IFERROR(VLOOKUP(AX29,'Geração Equatorial x Medido'!$O$4:$P$55,2,FALSE),"") | BB30: =IF(BA30="",BB31,BA30) -> 45658 | BC30: =IFERROR(VLOOKUP(AX30,$H$422:$J$457,3,FALSE),"") | BD30: =IF(BC30="",BD29,BC30) -> 45658 | BZ30: =BZ29+1 -> 46039 | CA30: 449.3 | CB30: =IF(CA30=0,1,0) -> 0 | CC30: =IFERROR(VLOOKUP(BZ29,'Geração Equatorial x Medido'!$O$4:$P$55,2,FALSE),"") | CD30: =IF(CC30="",CD31,CC30) -> 46023 | CE30: =IFERROR(VLOOKUP(BZ30,$H$422:$J$469,3,FALSE),"") | CF30: =IF(CE30="",CF29,CE30) -> 46023
... A93: =A92+1 -> 45016 | B93: 509.8 | C93: =IFERROR(VLOOKUP(A93,'Geração Equatorial x Medido'!$O$4:$P$15,2,FALSE),"") | D93: =IF(C93="",D92,C93) -> 44986 | E93: =IFERROR(VLOOKUP(A93,$H$422:$J$433,3,FALSE),"") | F93: =IF(E93="",F92,E93) -> 44986 | Y93: =Y92+1 -> 45376 | Z93: 418.4 | AA93: =IF(Z93=0,1,0) -> 0 | AB93: =IFERROR(VLOOKUP(Y93,'Geração Equatorial x Medido'!$O$15:$R$18,2,FALSE),"") | AC93: =IF(AB93="",AC92,AB93) -> 45323 | AD93: =IFERROR(VLOOKUP(Y93,$H$422:$J$457,3,FALSE),"") | AE93: =IF(AD93="",AE92,AD93) -> 45352 | AX93: =AX92+1 -> 45736 | AY93: 294.1 | AZ93: =IF(AY93=0,1,0) -> 0 | BA93: =IFERROR(VLOOKUP(AX92,'Geração Equatorial x Medido'!$O$4:$P$55,2,FALSE),"") | BB93: =IF(BA93="",BB94,BA93) -> 45717 | BC93: =IFERROR(VLOOKUP(AX93,$H$422:$J$457,3,FALSE),"") | BD93: =IF(BC93="",BD92,BC93) -> 45717 | BZ93: =BZ92+1 -> 46102 | CA93: 292.1 | CB93: =IF(CA93=0,1,0) -> 0 | CC93: =IFERROR(VLOOKUP(BZ92,'Geração Equatorial x Medido'!$O$4:$P$55,2,FALSE),"") | CD93: =IF(CC93="",CD94,CC93) -> 46082 | CE93: =IFERROR(VLOOKUP(BZ93,$H$422:$J$469,3,FALSE),"") | CF93: =IF(CE93="",CF92,CE93) -> 46082
